Workbook
Name \0: #REF!
Name \a: #REF!
Name \b: #N/A
Name \c: #N/A
Name \d: #REF!
Name \e: #REF!
Name \f: #N/A
Name \g: #N/A
Name \h: #N/A
Name \i: #REF!
Name \j: #N/A
Name \m: #REF!
Name \n: #REF!
Name \p: #N/A
Name \PAG1: #REF!
Name \PAG10: #REF!
Name \PAG11: #REF!
Name \PAG13: #REF!
Name \PAG14: #REF!
Name \PAG2: #REF!
Name \PAG3: #REF!
Name \PAG4: #REF!
Name \PAG5: #REF!
Name \PAG6: #REF!
Name \PAG7: #REF!
Name \PAG8: #REF!
Name \PAG9: #REF!
Name \q: #REF!
Name \r: #N/A
Name \s: #N/A
Name \t: #N/A
Name \u: #N/A
Name \v: #N/A
Name \x: #N/A
Name \z: #N/A
Name _: #REF!
Name ________________pl056: #REF!
Name _______________pl056: #REF!
Name ______________pl056: #REF!
Name _____________pl056: #REF!
Name ____________pl056: #REF!
Name ___________pl056: #REF!
Name __________pl056: #REF!
Name _________pl056: #REF!
Name ________pl056: #REF!
Name _______pl056: #REF!
Name ______COD1: #REF!
Name ______COD10: #REF!
Name ______COD11: #REF!
Name ______COD13: #REF!
Name ______COD138: #REF!
Name ______COD140: #REF!
Name ______COD144: #REF!
Name ______COD146: #REF!
Name ______COD149: #REF!
Name ______COD152: #REF!
Name ______COD154: #REF!
Name ______COD155: #REF!
Name ______COD156: #REF!
Name ______COD157: #REF!

Sheet PAINEL
O1: QTD SS
O2: =GETPIVOTDATA("STATUS. ENVIO",$B$5) -> #REF!
A3: (Tudo) | B3: TOMADOR | C3: (Tudo) | F3: TOMADOR | G3: (Tudo) | I3: TOMADOR | J3: (Tudo) | L3: TOMADOR | M3: (Tudo) | O3: TOMADOR | P3: (Tudo)
A5: R$ MEDIDO | F5: Rótulos de Linha | G5: Contagem de STATUS DEMANDA | I5: Rótulos de Linha | J5: Contagem de STATUS PRIMÁRIO (EC) | L5: Rótulos de Linha | M5: Contagem de STATUS SECUNDÁRIO (EC) | O5: R$ APROVADO | P5: R$ MEDIDO | Q5: R$ SALDO
A6: 2.120337e+08 | F6: CANCELADA | G6: 2 | I6: APROVADO | J6: 31 | L6: CANCELADA | M6: 2 | O6: 25645358 | P6: 14843092 | Q6: 10802266
F7: CONCLUÍDA | G7: 14 | I7: ON HOLD | J7: 3 | L7: EM PLANEJ. | M7: 1
F8: EM ANDAMENTO | G8: 17 | I8: FISCALIZ. | J8: 1 | L8: RETORNO OK | M8: 31
F9: EM PLANEJAMENTO | G9: 1 | I9: CANCELADA | J9: 2 | L9: ON HOLD | M9: 3
F10: ON HOLD | G10: 3 | I10: Total Geral | J10: 37 | L10: Total Geral | M10: 37
F11: Total Geral | G11: 37

Sheet INTEGRADO
E1: QTD SS | U1: FÍSICO | AE1: Hh
E2: =SUBTOTAL(9,A:A) -> 17
A3: CONT. | B3: Nº SS | C3: ID | DESCRIÇÃO DA DEMANDA | D3: TIPO | E3: TOMADOR | F3: STATUS DEMANDA | G3: ESTIMATIVA DE CUSTOS | O3: CRONOGRAMA | V3: ACOMPANHAMENTO FÍSICO | AB3: =SUBTOTAL(1,TB_INTEGRADA[DESVIO (%)]) -> -0.064717647 | AC3: =SUBTOTAL(9,TB_INTEGRADA[M.O PREV.]) -> 60 | AD3: =SUBTOTAL(9,TB_INTEGRADA[M.O REAL]) -> 64 | AF3: MECÂNICA | AJ3: CIVIL | AN3: ELÉTRICA | AR3: PINTURA | AV3: TOTAIS | AZ3: =SUBTOTAL(9,TB_INTEGRADA[R$ APROVADO]) -> 20337631 | BA3: =SUBTOTAL(9,TB_INTEGRADA[R$ MEDIDO ]) -> 9535364.5 | BB3: =SUBTOTAL(9,TB_INTEGRADA[R$ SALDO ]) -> 10802266
G4: ÚLTIMA REVISÃO | H4: ÚLTIMO ENVIO | I4: ÚLTIMA APROV. | J4: PRÓX. ENVIO | K4: STATUS ENVIO | L4: STATUS PRIMÁRIO | M4: AGUARD. RETORNO | N4: STATUS SECUNDÁRIO | O4: ÚLTIMA REVISÃO | P4: ÚLTIMO ENVIO | Q4: ÚLTIMA APROV. | R4: PRÓX. ENVIO | S4: STATUS ENVIO | T4: STATUS PRIMÁRIO | V4: TÉRM. LB | W4: TÉRM. TD | X4: DESVIO (d) | Y4: PREV (%) | Z4: REAL (%) | AA4: DESVIO ANT (%) ANT | AB4: DESVIO ATUAL (%) ATUAL | AC4: M.O PREV. | AD4: M.O REAL | AF4: ORÇADO | AG4: ORÇ DIG | AH4: PLANEJ | AI4: REALIZ | AJ4: ORÇADO | AK4: ORÇ DIG | AL4: PLANEJ | AM4: REALIZ | AN4: ORÇADO | AO4: ORÇ DIG | AP4: PLANEJ | AQ4: REALIZ | AR4: ORÇADO | AS4: ORÇ DIG | AT4: PLANEJ | AU4: REALIZ | AV4: ORÇADO | AW4: PLANEJ | AX4: REALIZ | AY4: % EXEC | AZ4: R$ APROVADO | BA4: R$ MEDIDO | BB4: R$ SALDO
A5: CONT. | B5: Nº SS | C5: ID | TÍTULO DA DEMANDA | D5: TIPO | E5: TOMADOR | F5: STATUS DEMANDA | G5: REVISÃO (EC) | H5: DATA ENVIO. (EC) | I5: DATA APROV. (EC) | J5: PRÓX. ENVIO | K5: STATUS ENVIO | L5: STATUS PRIMÁRIO (EC) | M5: AGUARD. RETORNO | N5: STATUS SECUNDÁRIO (EC) | O5: REVISÃO (CR) | P5: DATA ENVIO. (CR) | Q5: DATA APROV. (CR) | R5: PRÓX. ENVIO2 | S5: STATUS ENVIO | T5: STATUS PRIMÁRIO (EC) | U5: FÍSICO | V5: TÉRMINO LB | W5: TÉRM. TD | X5: DESVIO (d) | Y5: PREV (%) | Z5: REAL (%) | AA5: DESVIO (%) ANT | AB5: DESVIO (%) | AC5: M.O PREV. | AD5: M.O REAL | AE5: CONTR HH | AF5: ORÇADO | AG5: ORÇ DIG | AH5: PLANEJ | AI5: REALIZ | AJ5: ORÇADO1 | AK5: ORÇ DIG1 | AL5: PLANEJ1 | AM5: REALIZ1 | AN5: ORÇADO2 | AO5: ORÇ DIG2 | AP5: PLANEJ2 | AQ5: REALIZ2 | AR5: ORÇADO3 | AS5: ORÇ DIG3 | AT5: PLANEJ3 | AU5: REALIZ3 | AV5: ORÇADO4 | AW5: PLANEJ4 | AX5: REALIZ4 | AY5: % EXEC | AZ5: R$ APROVADO | BA5: R$ MEDIDO | BB5: R$ SALDO
A6: =IF(COUNTIFS($B$5:B6,TB_INTEGRADA[[#This Row],[Nº SS]])<>1,"",COUNTIFS($B$5:B6,TB_INTEGRADA[[#This Row],[Nº SS]])) -> 1 | B6: SS-01/2025 | C6: =_xlfn.XLOOKUP(TB_INTEGRADA[[#This Row],[Nº SS]],'CONTROLE EC'!B:B,'CONTROLE EC'!C:C,"",0,1) -> -- IMPLANTAÇÃO ÁREA I (EDIVIT, UTG-SUL, TIMS) | D6: =_xlfn.XLOOKUP(TB_INTEGRADA[[#This Row],[Nº SS]],'CONTROLE CRONOG'!B:B,'CONTROLE CRONOG'!D:D,"",0,1) -> ADM | E6: =_xlfn.XLOOKUP(TB_INTEGRADA[[#This Row],[Nº SS]],'CONTROLE EC'!B:B,'CONTROLE EC'!E:E,"",0,1) -> EDIVIT | F6: =_xlfn.XLOOKUP(TB_INTEGRADA[[#This Row],[Nº SS]],'CONTROLE EC'!B:B,'CONTROLE EC'!F:F,"",0,1) -> EM ANDAMENTO | G6: =_xlfn.XLOOKUP(TB_INTEGRADA[[#This Row],[Nº SS]],'CONTROLE EC'!B:B,'CONTROLE EC'!R:R,"",0,1) -> REV.00 | H6: =IF(TB_INTEGRADA[[#This Row],[REVISÃO (EC)]]="","",_xlfn.XLOOKUP(TB_INTEGRADA[[#This Row],[Nº SS]],'CONTROLE EC'!B:B,'CONTROLE EC'!S:S,"",0,1)) -> N/A | I6: =IF(TB_INTEGRADA[[#This Row],[REVISÃO (EC)]]="","",_xlfn.XLOOKUP(TB_INTEGRADA[[#This Row],[Nº SS]],'CONTROLE EC'!B:B,'CONTROLE EC'!U:U,"",0,1)) -> N/A | J6: {=IF(TB_INTEGRADA[[#This Row],[DATA ENVIO. (EC)]]=IFERROR(INDEX('CONTROLE EC'!G6:Q6,MATCH(2,1/('CONTROLE EC'!G6:Q6<>""))),""),"",IFERROR(INDEX('CONTROLE EC'!G6:Q6,MATCH(2,1/('CONTROLE EC'!G6:Q6<>""))),""))} | K6: =IF(TB_INTEGRADA[[#This Row],[STATUS DEMANDA]]="NÃO EMITIDA SAMC","S/ EMISSÃO",_xlfn.XLOOKUP(TB_INTEGRADA[[#This Row],[Nº SS]],'CONTROLE EC'!B:B,'CONTROLE EC'!T:T,"",0,-1)) -> ENTREGUE | L6: =IF(TB_INTEGRADA[[#This Row],[STATUS DEMANDA]]="NÃO EMITIDA SAMC","S/ EMISSÃO",IF(TB_INTEGRADA[[#This Row],[STATUS DEMANDA]]="ON HOLD","ON HOLD",IF(TB_INTEGRADA[[#This Row],[STATUS DEMANDA]]="CANCELADA","CANCELADA",IF(TB_INTEGRADA[[#This Row],[DATA APROV. (EC)]]=0,"FISCALIZ.",IF(TB_INTEGRADA[[#This Row],[DATA APROV. (EC)]]="","PEND. FISCALIZ.",IF(TB_INTEGRADA[[#This Row],[DATA APROV. (EC)]]="N/A","APROVADO",IF(TB_INTEGRADA[[#This Row],[REVISÃO (EC)]]="","",_xlfn.XLOOKUP(TB_INTEGRADA[[#This Row],[Nº SS]],'CONTROLE EC'!B:B,'CONTROLE EC'!V:V,"",0,1)))))))) -> APROVADO | M6: {=IFERROR(_xlfn.IFS(TB_INTEGRADA[[#This Row],[STATUS DEMANDA]]="CANCELADA",0,TB_INTEGRADA[[#This Row],[DATA APROV. (EC)]]="",TODAY()-TB_INTEGRADA[[#This Row],[DATA ENVIO. (EC)]],TB_INTEGRADA[[#This Row],[DATA APROV. (EC)]]>=TB_INTEGRADA[[#This Row],[DATA ENVIO. (EC)]],0,TB_INTEGRADA[[#This Row],[DATA ENVIO. (EC)]]="",0,TB_INTEGRADA[[#This Row],[DATA ENVIO. (EC)]]>TB_INTEGRADA[[#This Row],[DATA APROV. (EC)]],TODAY()-TB_INTEGRADA[[#This Row],[DATA ENVIO. (EC)]]),"")} -> 0 | N6: =IF(TB_INTEGRADA[[#This Row],[STATUS DEMANDA]]="NÃO EMITIDA SAMC","S/ EMISSÃO",IF(TB_INTEGRADA[[#This Row],[STATUS DEMANDA]]="ON HOLD","ON HOLD",IF(F6="CANCELADA","CANCELADA",IF(L6="REPROVADO","EM PLANEJ.",IF(K6<>"ENTREGUE","EM PLANEJ.",IF(H6="","EM PLANEJ.",IF(I6="","FISCALIZ.",IF(M6<0,"EM PLANEJ.",IF(TB_INTEGRADA[[#This Row],[DATA APROV. (EC)]]>=TB_INTEGRADA[[#This Row],[DATA ENVIO. (EC)]],"RETORNO OK","FISCALIZ."))))))))) -> RETORNO OK | O6: =_xlfn.XLOOKUP(TB_INTEGRADA[[#This Row],[Nº SS]],'CONTROLE CRONOG'!B:B,'CONTROLE CRONOG'!R:R,"",0,1) -> REV.00 | P6: =IF(TB_INTEGRADA[[#This Row],[REVISÃO (CR)]]="","",_xlfn.XLOOKUP(TB_INTEGRADA[[#This Row],[Nº SS]],'CONTROLE CRONOG'!B:B,'CONTROLE CRONOG'!S:S,"",0,1)) -> N/A | Q6: =IF(TB_INTEGRADA[[#This Row],[REVISÃO (CR)]]="","",_xlfn.XLOOKUP(TB_INTEGRADA[[#This Row],[Nº SS]],'CONTROLE CRONOG'!B:B,'CONTROLE CRONOG'!U:U,"",0,1)) -> N/A | R6: {=IF(TB_INTEGRADA[[#This Row],[DATA ENVIO. (CR)]]=IFERROR(INDEX('CONTROLE CRONOG'!G6:Q6,MATCH(2,1/('CONTROLE CRONOG'!G6:Q6<>""))),""),"",IFERROR(INDEX('CONTROLE CRONOG'!G6:Q6,MATCH(2,1/('CONTROLE CRONOG'!G6:Q6<>""))),""))} | S6: =_xlfn.XLOOKUP(TB_INTEGRADA[[#This Row],[Nº SS]],'CONTROLE CRONOG'!B:B,'CONTROLE CRONOG'!T:T,"",0,-1) -> ENTREGUE | T6: =IF(TB_INTEGRADA[[#This Row],[STATUS DEMANDA]]="ON HOLD","ON HOLD",IF(TB_INTEGRADA[[#This Row],[STATUS DEMANDA]]="CANCELADA","CANCELADA",IF(TB_INTEGRADA[[#This Row],[DATA APROV. (CR)]]=0,"FISCALIZ.",IF(TB_INTEGRADA[[#This Row],[DATA APROV. (CR)]]="N/A","APROVADO",IF(TB_INTEGRADA[[#This Row],[REVISÃO (CR)]]="","",_xlfn.XLOOKUP(TB_INTEGRADA[[#This Row],[Nº SS]],'CONTROLE CRONOG'!B:B,'CONTROLE CRONOG'!V:V,"",0,1)))))) -> APROVADO | X6: =IFERROR(TB_INTEGRADA[[#This Row],[TÉRM. TD]]-TB_INTEGRADA[[#This Row],[TÉRMINO LB]],0) -> 0 | AB6: =IFERROR(TB_INTEGRADA[[#This Row],[REAL (%)]]-TB_INTEGRADA[[#This Row],[PREV (%)]],0) -> 0 | AF6: =IF(TB_INTEGRADA[[#This Row],[TOMADOR]]="EDIVIT",TB_INTEGRADA[[#This Row],[ORÇ DIG]]*1.38,IF(TB_INTEGRADA[[#This Row],[TOMADOR]]="UTGC",TB_INTEGRADA[[#This Row],[ORÇ DIG]]*1.47,IF(TB_INTEGRADA[[#This Row],[TOMADOR]]="TIMS",TB_INTEGRADA[[#This Row],[ORÇ DIG]]*1.34,IF(TB_INTEGRADA[[#This Row],[TOMADOR]]="UTGSUL",TB_INTEGRADA[[#This Row],[ORÇ DIG]]*1.37,IF(TB_INTEGRADA[[#This Row],[TOMADOR]]="REGAP",TB_INTEGRADA[[#This Row],[ORÇ DIG]]*1.36,IF(TB_INTEGRADA[[#This Row],[TOMADOR]]="UTEIBI",TB_INTEGRADA[[#This Row],[ORÇ DIG]]*1.5,"S/TOMADOR")))))) -> 0 | AH6: =SUMIFS(Tb_HhPLAN[Hh DISC],Tb_HhPLAN[SS],TB_INTEGRADA[[#This Row],[Nº SS]],Tb_HhPLAN[DISCIPLINA],"MEC") -> 0 | AI6: =SUMIFS(Hh_EXE_TOTAL[Hh],Hh_EXE_TOTAL[Nº SS],TB_INTEGRADA[[#This Row],[Nº SS]],Hh_EXE_TOTAL[DISCIPLINA],"MEC") -> 0 | AJ6: =IF(TB_INTEGRADA[[#This Row],[TOMADOR]]="EDIVIT",TB_INTEGRADA[[#This Row],[ORÇ DIG1]]*1.38,IF(TB_INTEGRADA[[#This Row],[TOMADOR]]="UTGC",TB_INTEGRADA[[#This Row],[ORÇ DIG1]]*1.47,IF(TB_INTEGRADA[[#This Row],[TOMADOR]]="TIMS",TB_INTEGRADA[[#This Row],[ORÇ DIG1]]*1.34,IF(TB_INTEGRADA[[#This Row],[TOMADOR]]="UTGSUL",TB_INTEGRADA[[#This Row],[ORÇ DIG1]]*1.37,IF(TB_INTEGRADA[[#This Row],[TOMADOR]]="REGAP",TB_INTEGRADA[[#This Row],[ORÇ DIG1]]*1.36,IF(TB_INTEGRADA[[#This Row],[TOMADOR]]="UTEIBI",TB_INTEGRADA[[#This Row],[ORÇ DIG1]]*1.5,"S/TOMADOR")))))) -> 0 | AL6: =SUMIFS(Tb_HhPLAN[Hh DISC],Tb_HhPLAN[SS],TB_INTEGRADA[[#This Row],[Nº SS]],Tb_HhPLAN[DISCIPLINA],"CIVIL") -> 0 | AM6: =SUMIFS(Hh_EXE_TOTAL[Hh],Hh_EXE_TOTAL[Nº SS],TB_INTEGRADA[[#This Row],[Nº SS]],Hh_EXE_TOTAL[DISCIPLINA],"CIVIL") -> 0 | AN6: =IF(TB_INTEGRADA[[#This Row],[TOMADOR]]="EDIVIT",TB_INTEGRADA[[#This Row],[ORÇ DIG2]]*1.38,IF(TB_INTEGRADA[[#This Row],[TOMADOR]]="UTGC",TB_INTEGRADA[[#This Row],[ORÇ DIG2]]*1.47,IF(TB_INTEGRADA[[#This Row],[TOMADOR]]="TIMS",TB_INTEGRADA[[#This Row],[ORÇ DIG2]]*1.34,IF(TB_INTEGRADA[[#This Row],[TOMADOR]]="UTGSUL",TB_INTEGRADA[[#This Row],[ORÇ DIG2]]*1.37,IF(TB_INTEGRADA[[#This Row],[TOMADOR]]="REGAP",TB_INTEGRADA[[#This Row],[ORÇ DIG2]]*1.36,IF(TB_INTEGRADA[[#This Row],[TOMADOR]]="UTEIBI",TB_INTEGRADA[[#This Row],[ORÇ DIG2]]*1.5,"S/TOMADOR")))))) -> 0 | AP6: =SUMIFS(Tb_HhPLAN[Hh DISC],Tb_HhPLAN[SS],TB_INTEGRADA[[#This Row],[Nº SS]],Tb_HhPLAN[DISCIPLINA],"ELÉT") -> 0 | AQ6: =SUMIFS(Hh_EXE_TOTAL[Hh],Hh_EXE_TOTAL[Nº SS],TB_INTEGRADA[[#This Row],[Nº SS]],Hh_EXE_TOTAL[DISCIPLINA],"ELÉT") -> 0 | AR6: =IF(TB_INTEGRADA[[#This Row],[TOMADOR]]="EDIVIT",TB_INTEGRADA[[#This Row],[ORÇ DIG3]]*1.38,IF(TB_INTEGRADA[[#This Row],[TOMADOR]]="UTGC",TB_INTEGRADA[[#This Row],[ORÇ DIG3]]*1.47,IF(TB_INTEGRADA[[#This Row],[TOMADOR]]="TIMS",TB_INTEGRADA[[#This Row],[ORÇ DIG3]]*1.34,IF(TB_INTEGRADA[[#This Row],[TOMADOR]]="UTGSUL",TB_INTEGRADA[[#This Row],[ORÇ DIG3]]*1.37,IF(TB_INTEGRADA[[#This Row],[TOMADOR]]="REGAP",TB_INTEGRADA[[#This Row],[ORÇ DIG3]]*1.36,IF(TB_INTEGRADA[[#This Row],[TOMADOR]]="UTEIBI",TB_INTEGRADA[[#This Row],[ORÇ DIG3]]*1.5,"S/TOMADOR")))))) -> 0 | AT6: =SUMIFS(Tb_HhPLAN[Hh DISC],Tb_HhPLAN[SS],TB_INTEGRADA[[#This Row],[Nº SS]],Tb_HhPLAN[DISCIPLINA],"PINT") -> 0 | AU6: =SUMIFS(Hh_EXE_TOTAL[Hh],Hh_EXE_TOTAL[Nº SS],TB_INTEGRADA[[#This Row],[Nº SS]],Hh_EXE_TOTAL[DISCIPLINA],"PINT") -> 0 | AV6: =TB_INTEGRADA[[#This Row],[ORÇADO]]+TB_INTEGRADA[[#This Row],[ORÇADO1]]+TB_INTEGRADA[[#This Row],[ORÇADO2]]+TB_INTEGRADA[[#This Row],[ORÇADO3]] -> 0 | AW6: =TB_INTEGRADA[[#This Row],[PLANEJ]]+TB_INTEGRADA[[#This Row],[PLANEJ1]]+TB_INTEGRADA[[#This Row],[PLANEJ2]]+TB_INTEGRADA[[#This Row],[PLANEJ3]] -> 0 | AX6: =TB_INTEGRADA[[#This Row],[REALIZ]]+TB_INTEGRADA[[#This Row],[REALIZ1]]+TB_INTEGRADA[[#This Row],[REALIZ2]]+TB_INTEGRADA[[#This Row],[REALIZ3]] -> 0 | AZ6: =_xlfn.XLOOKUP(TB_INTEGRADA[[#This Row],[Nº SS]],'CONTROLE EC'!B:B,'CONTROLE EC'!W:W,"",0,1) -> 7940511.1 | BA6: =_xlfn.XLOOKUP(TB_INTEGRADA[[#This Row],[Nº SS]],'CONTROLE EC'!B:B,'CONTROLE EC'!X:X,"",0,1) -> 2080364.8 | BB6: =_xlfn.XLOOKUP(TB_INTEGRADA[[#This Row],[Nº SS]],'CONTROLE EC'!B:B,'CONTROLE EC'!Y:Y,"",0,1) -> 5860146.3
A7: =IF(COUNTIFS($B$5:B7,TB_INTEGRADA[[#This Row],[Nº SS]])<>1,"",COUNTIFS($B$5:B7,TB_INTEGRADA[[#This Row],[Nº SS]])) -> 1 | B7: SS-02/2025 | C7: =_xlfn.XLOOKUP(TB_INTEGRADA[[#This Row],[Nº SS]],'CONTROLE EC'!B:B,'CONTROLE EC'!C:C,"",0,1) -> -- IMPLANTAÇÃO ÁREA II (UTGC) | D7: =_xlfn.XLOOKUP(TB_INTEGRADA[[#This Row],[Nº SS]],'CONTROLE CRONOG'!B:B,'CONTROLE CRONOG'!D:D,"",0,1) -> ADM | E7: =_xlfn.XLOOKUP(TB_INTEGRADA[[#This Row],[Nº SS]],'CONTROLE EC'!B:B,'CONTROLE EC'!E:E,"",0,1) -> UTGC | F7: =_xlfn.XLOOKUP(TB_INTEGRADA[[#This Row],[Nº SS]],'CONTROLE EC'!B:B,'CONTROLE EC'!F:F,"",0,1) -> EM ANDAMENTO | G7: =_xlfn.XLOOKUP(TB_INTEGRADA[[#This Row],[Nº SS]],'CONTROLE EC'!B:B,'CONTROLE EC'!R:R,"",0,1) -> REV.00 | H7: =IF(TB_INTEGRADA[[#This Row],[REVISÃO (EC)]]="","",_xlfn.XLOOKUP(TB_INTEGRADA[[#This Row],[Nº SS]],'CONTROLE EC'!B:B,'CONTROLE EC'!S:S,"",0,1)) -> N/A | I7: =IF(TB_INTEGRADA[[#This Row],[REVISÃO (EC)]]="","",_xlfn.XLOOKUP(TB_INTEGRADA[[#This Row],[Nº SS]],'CONTROLE EC'!B:B,'CONTROLE EC'!U:U,"",0,1)) -> N/A | J7: {=IF(TB_INTEGRADA[[#This Row],[DATA ENVIO. (EC)]]=IFERROR(INDEX('CONTROLE EC'!G7:Q7,MATCH(2,1/('CONTROLE EC'!G7:Q7<>""))),""),"",IFERROR(INDEX('CONTROLE EC'!G7:Q7,MATCH(2,1/('CONTROLE EC'!G7:Q7<>""))),""))} | K7: =IF(TB_INTEGRADA[[#This Row],[STATUS DEMANDA]]="NÃO EMITIDA SAMC","S/ EMISSÃO",_xlfn.XLOOKUP(TB_INTEGRADA[[#This Row],[Nº SS]],'CONTROLE EC'!B:B,'CONTROLE EC'!T:T,"",0,-1)) -> ENTREGUE | L7: =IF(TB_INTEGRADA[[#This Row],[STATUS DEMANDA]]="NÃO EMITIDA SAMC","S/ EMISSÃO",IF(TB_INTEGRADA[[#This Row],[STATUS DEMANDA]]="ON HOLD","ON HOLD",IF(TB_INTEGRADA[[#This Row],[STATUS DEMANDA]]="CANCELADA","CANCELADA",IF(TB_INTEGRADA[[#This Row],[DATA APROV. (EC)]]=0,"FISCALIZ.",IF(TB_INTEGRADA[[#This Row],[DATA APROV. (EC)]]="","PEND. FISCALIZ.",IF(TB_INTEGRADA[[#This Row],[DATA APROV. (EC)]]="N/A","APROVADO",IF(TB_INTEGRADA[[#This Row],[REVISÃO (EC)]]="","",_xlfn.XLOOKUP(TB_INTEGRADA[[#This Row],[Nº SS]],'CONTROLE EC'!B:B,'CONTROLE EC'!V:V,"",0,1)))))))) -> APROVADO | M7: {=IFERROR(_xlfn.IFS(TB_INTEGRADA[[#This Row],[STATUS DEMANDA]]="CANCELADA",0,TB_INTEGRADA[[#This Row],[DATA APROV. (EC)]]="",TODAY()-TB_INTEGRADA[[#This Row],[DATA ENVIO. (EC)]],TB_INTEGRADA[[#This Row],[DATA APROV. (EC)]]>=TB_INTEGRADA[[#This Row],[DATA ENVIO. (EC)]],0,TB_INTEGRADA[[#This Row],[DATA ENVIO. (EC)]]="",0,TB_INTEGRADA[[#This Row],[DATA ENVIO. (EC)]]>TB_INTEGRADA[[#This Row],[DATA APROV. (EC)]],TODAY()-TB_INTEGRADA[[#This Row],[DATA ENVIO. (EC)]]),"")} -> 0 | N7: =IF(TB_INTEGRADA[[#This Row],[STATUS DEMANDA]]="NÃO EMITIDA SAMC","S/ EMISSÃO",IF(TB_INTEGRADA[[#This Row],[STATUS DEMANDA]]="ON HOLD","ON HOLD",IF(F7="CANCELADA","CANCELADA",IF(L7="REPROVADO","EM PLANEJ.",IF(K7<>"ENTREGUE","EM PLANEJ.",IF(H7="","EM PLANEJ.",IF(I7="","FISCALIZ.",IF(M7<0,"EM PLANEJ.",IF(TB_INTEGRADA[[#This Row],[DATA APROV. (EC)]]>=TB_INTEGRADA[[#This Row],[DATA ENVIO. (EC)]],"RETORNO OK","FISCALIZ."))))))))) -> RETORNO OK | O7: =_xlfn.XLOOKUP(TB_INTEGRADA[[#This Row],[Nº SS]],'CONTROLE CRONOG'!B:B,'CONTROLE CRONOG'!R:R,"",0,1) -> REV.00 | P7: =IF(TB_INTEGRADA[[#This Row],[REVISÃO (CR)]]="","",_xlfn.XLOOKUP(TB_INTEGRADA[[#This Row],[Nº SS]],'CONTROLE CRONOG'!B:B,'CONTROLE CRONOG'!S:S,"",0,1)) -> N/A | Q7: =IF(TB_INTEGRADA[[#This Row],[REVISÃO (CR)]]="","",_xlfn.XLOOKUP(TB_INTEGRADA[[#This Row],[Nº SS]],'CONTROLE CRONOG'!B:B,'CONTROLE CRONOG'!U:U,"",0,1)) -> N/A | R7: {=IF(TB_INTEGRADA[[#This Row],[DATA ENVIO. (CR)]]=IFERROR(INDEX('CONTROLE CRONOG'!G7:Q7,MATCH(2,1/('CONTROLE CRONOG'!G7:Q7<>""))),""),"",IFERROR(INDEX('CONTROLE CRONOG'!G7:Q7,MATCH(2,1/('CONTROLE CRONOG'!G7:Q7<>""))),""))} | S7: =_xlfn.XLOOKUP(TB_INTEGRADA[[#This Row],[Nº SS]],'CONTROLE CRONOG'!B:B,'CONTROLE CRONOG'!T:T,"",0,-1) -> ENTREGUE | T7: =IF(TB_INTEGRADA[[#This Row],[STATUS DEMANDA]]="ON HOLD","ON HOLD",IF(TB_INTEGRADA[[#This Row],[STATUS DEMANDA]]="CANCELADA","CANCELADA",IF(TB_INTEGRADA[[#This Row],[DATA APROV. (CR)]]=0,"FISCALIZ.",IF(TB_INTEGRADA[[#This Row],[DATA APROV. (CR)]]="N/A","APROVADO",IF(TB_INTEGRADA[[#This Row],[REVISÃO (CR)]]="","",_xlfn.XLOOKUP(TB_INTEGRADA[[#This Row],[Nº SS]],'CONTROLE CRONOG'!B:B,'CONTROLE CRONOG'!V:V,"",0,1)))))) -> APROVADO | X7: =IFERROR(TB_INTEGRADA[[#This Row],[TÉRM. TD]]-TB_INTEGRADA[[#This Row],[TÉRMINO LB]],0) -> 0 | AB7: =IFERROR(TB_INTEGRADA[[#This Row],[REAL (%)]]-TB_INTEGRADA[[#This Row],[PREV (%)]],0) -> 0 | AF7: =IF(TB_INTEGRADA[[#This Row],[TOMADOR]]="EDIVIT",TB_INTEGRADA[[#This Row],[ORÇ DIG]]*1.38,IF(TB_INTEGRADA[[#This Row],[TOMADOR]]="UTGC",TB_INTEGRADA[[#This Row],[ORÇ DIG]]*1.47,IF(TB_INTEGRADA[[#This Row],[TOMADOR]]="TIMS",TB_INTEGRADA[[#This Row],[ORÇ DIG]]*1.34,IF(TB_INTEGRADA[[#This Row],[TOMADOR]]="UTGSUL",TB_INTEGRADA[[#This Row],[ORÇ DIG]]*1.37,IF(TB_INTEGRADA[[#This Row],[TOMADOR]]="REGAP",TB_INTEGRADA[[#This Row],[ORÇ DIG]]*1.36,IF(TB_INTEGRADA[[#This Row],[TOMADOR]]="UTEIBI",TB_INTEGRADA[[#This Row],[ORÇ DIG]]*1.5,"S/TOMADOR")))))) -> 0 | AH7: =SUMIFS(Tb_HhPLAN[Hh DISC],Tb_HhPLAN[SS],TB_INTEGRADA[[#This Row],[Nº SS]],Tb_HhPLAN[DISCIPLINA],"MEC") -> 0 | AI7: =SUMIFS(Hh_EXE_TOTAL[Hh],Hh_EXE_TOTAL[Nº SS],TB_INTEGRADA[[#This Row],[Nº SS]],Hh_EXE_TOTAL[DISCIPLINA],"MEC") -> 0 | AJ7: =IF(TB_INTEGRADA[[#This Row],[TOMADOR]]="EDIVIT",TB_INTEGRADA[[#This Row],[ORÇ DIG1]]*1.38,IF(TB_INTEGRADA[[#This Row],[TOMADOR]]="UTGC",TB_INTEGRADA[[#This Row],[ORÇ DIG1]]*1.47,IF(TB_INTEGRADA[[#This Row],[TOMADOR]]="TIMS",TB_INTEGRADA[[#This Row],[ORÇ DIG1]]*1.34,IF(TB_INTEGRADA[[#This Row],[TOMADOR]]="UTGSUL",TB_INTEGRADA[[#This Row],[ORÇ DIG1]]*1.37,IF(TB_INTEGRADA[[#This Row],[TOMADOR]]="REGAP",TB_INTEGRADA[[#This Row],[ORÇ DIG1]]*1.36,IF(TB_INTEGRADA[[#This Row],[TOMADOR]]="UTEIBI",TB_INTEGRADA[[#This Row],[ORÇ DIG1]]*1.5,"S/TOMADOR")))))) -> 0 | AL7: =SUMIFS(Tb_HhPLAN[Hh DISC],Tb_HhPLAN[SS],TB_INTEGRADA[[#This Row],[Nº SS]],Tb_HhPLAN[DISCIPLINA],"CIVIL") -> 0 | AM7: =SUMIFS(Hh_EXE_TOTAL[Hh],Hh_EXE_TOTAL[Nº SS],TB_INTEGRADA[[#This Row],[Nº SS]],Hh_EXE_TOTAL[DISCIPLINA],"CIVIL") -> 0 | AN7: =IF(TB_INTEGRADA[[#This Row],[TOMADOR]]="EDIVIT",TB_INTEGRADA[[#This Row],[ORÇ DIG2]]*1.38,IF(TB_INTEGRADA[[#This Row],[TOMADOR]]="UTGC",TB_INTEGRADA[[#This Row],[ORÇ DIG2]]*1.47,IF(TB_INTEGRADA[[#This Row],[TOMADOR]]="TIMS",TB_INTEGRADA[[#This Row],[ORÇ DIG2]]*1.34,IF(TB_INTEGRADA[[#This Row],[TOMADOR]]="UTGSUL",TB_INTEGRADA[[#This Row],[ORÇ DIG2]]*1.37,IF(TB_INTEGRADA[[#This Row],[TOMADOR]]="REGAP",TB_INTEGRADA[[#This Row],[ORÇ DIG2]]*1.36,IF(TB_INTEGRADA[[#This Row],[TOMADOR]]="UTEIBI",TB_INTEGRADA[[#This Row],[ORÇ DIG2]]*1.5,"S/TOMADOR")))))) -> 0 | AP7: =SUMIFS(Tb_HhPLAN[Hh DISC],Tb_HhPLAN[SS],TB_INTEGRADA[[#This Row],[Nº SS]],Tb_HhPLAN[DISCIPLINA],"ELÉT") -> 0 | AQ7: =SUMIFS(Hh_EXE_TOTAL[Hh],Hh_EXE_TOTAL[Nº SS],TB_INTEGRADA[[#This Row],[Nº SS]],Hh_EXE_TOTAL[DISCIPLINA],"ELÉT") -> 0 | AR7: =IF(TB_INTEGRADA[[#This Row],[TOMADOR]]="EDIVIT",TB_INTEGRADA[[#This Row],[ORÇ DIG3]]*1.38,IF(TB_INTEGRADA[[#This Row],[TOMADOR]]="UTGC",TB_INTEGRADA[[#This Row],[ORÇ DIG3]]*1.47,IF(TB_INTEGRADA[[#This Row],[TOMADOR]]="TIMS",TB_INTEGRADA[[#This Row],[ORÇ DIG3]]*1.34,IF(TB_INTEGRADA[[#This Row],[TOMADOR]]="UTGSUL",TB_INTEGRADA[[#This Row],[ORÇ DIG3]]*1.37,IF(TB_INTEGRADA[[#This Row],[TOMADOR]]="REGAP",TB_INTEGRADA[[#This Row],[ORÇ DIG3]]*1.36,IF(TB_INTEGRADA[[#This Row],[TOMADOR]]="UTEIBI",TB_INTEGRADA[[#This Row],[ORÇ DIG3]]*1.5,"S/TOMADOR")))))) -> 0 | AT7: =SUMIFS(Tb_HhPLAN[Hh DISC],Tb_HhPLAN[SS],TB_INTEGRADA[[#This Row],[Nº SS]],Tb_HhPLAN[DISCIPLINA],"PINT") -> 0 | AU7: =SUMIFS(Hh_EXE_TOTAL[Hh],Hh_EXE_TOTAL[Nº SS],TB_INTEGRADA[[#This Row],[Nº SS]],Hh_EXE_TOTAL[DISCIPLINA],"PINT") -> 0 | AV7: =TB_INTEGRADA[[#This Row],[ORÇADO]]+TB_INTEGRADA[[#This Row],[ORÇADO1]]+TB_INTEGRADA[[#This Row],[ORÇADO2]]+TB_INTEGRADA[[#This Row],[ORÇADO3]] -> 0 | AW7: =TB_INTEGRADA[[#This Row],[PLANEJ]]+TB_INTEGRADA[[#This Row],[PLANEJ1]]+TB_INTEGRADA[[#This Row],[PLANEJ2]]+TB_INTEGRADA[[#This Row],[PLANEJ3]] -> 0 | AX7: =TB_INTEGRADA[[#This Row],[REALIZ]]+TB_INTEGRADA[[#This Row],[REALIZ1]]+TB_INTEGRADA[[#This Row],[REALIZ2]]+TB_INTEGRADA[[#This Row],[REALIZ3]] -> 0 | AZ7: =_xlfn.XLOOKUP(TB_INTEGRADA[[#This Row],[Nº SS]],'CONTROLE EC'!B:B,'CONTROLE EC'!W:W,"",0,1) -> 10320001 | BA7: =_xlfn.XLOOKUP(TB_INTEGRADA[[#This Row],[Nº SS]],'CONTROLE EC'!B:B,'CONTROLE EC'!X:X,"",0,1) -> 3321231.8 | BB7: =_xlfn.XLOOKUP(TB_INTEGRADA[[#This Row],[Nº SS]],'CONTROLE EC'!B:B,'CONTROLE EC'!Y:Y,"",0,1) -> 6998769.5
A8: =IF(COUNTIFS($B$5:B8,TB_INTEGRADA[[#This Row],[Nº SS]])<>1,"",COUNTIFS($B$5:B8,TB_INTEGRADA[[#This Row],[Nº SS]])) -> 1 | B8: SS-03/2025 | C8: =_xlfn.XLOOKUP(TB_INTEGRADA[[#This Row],[Nº SS]],'CONTROLE EC'!B:B,'CONTROLE EC'!C:C,"",0,1) -> -- IMPLANTAÇÃO ÁREA III (REGAP, UTE-IBT) | D8: =_xlfn.XLOOKUP(TB_INTEGRADA[[#This Row],[Nº SS]],'CONTROLE CRONOG'!B:B,'CONTROLE CRONOG'!D:D,"",0,1) -> ADM | E8: =_xlfn.XLOOKUP(TB_INTEGRADA[[#This Row],[Nº SS]],'CONTROLE EC'!B:B,'CONTROLE EC'!E:E,"",0,1) -> REGAP | F8: =_xlfn.XLOOKUP(TB_INTEGRADA[[#This Row],[Nº SS]],'CONTROLE EC'!B:B,'CONTROLE EC'!F:F,"",0,1) -> NÃO EMITIDA SAMC | G8: =_xlfn.XLOOKUP(TB_INTEGRADA[[#This Row],[Nº SS]],'CONTROLE EC'!B:B,'CONTROLE EC'!R:R,"",0,1) | H8: =IF(TB_INTEGRADA[[#This Row],[REVISÃO (EC)]]="","",_xlfn.XLOOKUP(TB_INTEGRADA[[#This Row],[Nº SS]],'CONTROLE EC'!B:B,'CONTROLE EC'!S:S,"",0,1)) | I8: =IF(TB_INTEGRADA[[#This Row],[REVISÃO (EC)]]="","",_xlfn.XLOOKUP(TB_INTEGRADA[[#This Row],[Nº SS]],'CONTROLE EC'!B:B,'CONTROLE EC'!U:U,"",0,1)) | J8: {=IF(TB_INTEGRADA[[#This Row],[DATA ENVIO. (EC)]]=IFERROR(INDEX('CONTROLE EC'!G8:Q8,MATCH(2,1/('CONTROLE EC'!G8:Q8<>""))),""),"",IFERROR(INDEX('CONTROLE EC'!G8:Q8,MATCH(2,1/('CONTROLE EC'!G8:Q8<>""))),""))} | K8: =IF(TB_INTEGRADA[[#This Row],[STATUS DEMANDA]]="NÃO EMITIDA SAMC","S/ EMISSÃO",_xlfn.XLOOKUP(TB_INTEGRADA[[#This Row],[Nº SS]],'CONTROLE EC'!B:B,'CONTROLE EC'!T:T,"",0,-1)) -> S/ EMISSÃO | L8: =IF(TB_INTEGRADA[[#This Row],[STATUS DEMANDA]]="NÃO EMITIDA SAMC","S/ EMISSÃO",IF(TB_INTEGRADA[[#This Row],[STATUS DEMANDA]]="ON HOLD","ON HOLD",IF(TB_INTEGRADA[[#This Row],[STATUS DEMANDA]]="CANCELADA","CANCELADA",IF(TB_INTEGRADA[[#This Row],[DATA APROV. (EC)]]=0,"FISCALIZ.",IF(TB_INTEGRADA[[#This Row],[DATA APROV. (EC)]]="","PEND. FISCALIZ.",IF(TB_INTEGRADA[[#This Row],[DATA APROV. (EC)]]="N/A","APROVADO",IF(TB_INTEGRADA[[#This Row],[REVISÃO (EC)]]="","",_xlfn.XLOOKUP(TB_INTEGRADA[[#This Row],[Nº SS]],'CONTROLE EC'!B:B,'CONTROLE EC'!V:V,"",0,1)))))))) -> S/ EMISSÃO | M8: {=IFERROR(_xlfn.IFS(TB_INTEGRADA[[#This Row],[STATUS DEMANDA]]="CANCELADA",0,TB_INTEGRADA[[#This Row],[DATA APROV. (EC)]]="",TODAY()-TB_INTEGRADA[[#This Row],[DATA ENVIO. (EC)]],TB_INTEGRADA[[#This Row],[DATA APROV. (EC)]]>=TB_INTEGRADA[[#This Row],[DATA ENVIO. (EC)]],0,TB_INTEGRADA[[#This Row],[DATA ENVIO. (EC)]]="",0,TB_INTEGRADA[[#This Row],[DATA ENVIO. (EC)]]>TB_INTEGRADA[[#This Row],[DATA APROV. (EC)]],TODAY()-TB_INTEGRADA[[#This Row],[DATA ENVIO. (EC)]]),"")} | N8: =IF(TB_INTEGRADA[[#This Row],[STATUS DEMANDA]]="NÃO EMITIDA SAMC","S/ EMISSÃO",IF(TB_INTEGRADA[[#This Row],[STATUS DEMANDA]]="ON HOLD","ON HOLD",IF(F8="CANCELADA","CANCELADA",IF(L8="REPROVADO","EM PLANEJ.",IF(K8<>"ENTREGUE","EM PLANEJ.",IF(H8="","EM PLANEJ.",IF(I8="","FISCALIZ.",IF(M8<0,"EM PLANEJ.",IF(TB_INTEGRADA[[#This Row],[DATA APROV. (EC)]]>=TB_INTEGRADA[[#This Row],[DATA ENVIO. (EC)]],"RETORNO OK","FISCALIZ."))))))))) -> S/ EMISSÃO | O8: =_xlfn.XLOOKUP(TB_INTEGRADA[[#This Row],[Nº SS]],'CONTROLE CRONOG'!B:B,'CONTROLE CRONOG'!R:R,"",0,1) | P8: =IF(TB_INTEGRADA[[#This Row],[REVISÃO (CR)]]="","",_xlfn.XLOOKUP(TB_INTEGRADA[[#This Row],[Nº SS]],'CONTROLE CRONOG'!B:B,'CONTROLE CRONOG'!S:S,"",0,1)) | Q8: =IF(TB_INTEGRADA[[#This Row],[REVISÃO (CR)]]="","",_xlfn.XLOOKUP(TB_INTEGRADA[[#This Row],[Nº SS]],'CONTROLE CRONOG'!B:B,'CONTROLE CRONOG'!U:U,"",0,1)) | R8: {=IF(TB_INTEGRADA[[#This Row],[DATA ENVIO. (CR)]]=IFERROR(INDEX('CONTROLE CRONOG'!G8:Q8,MATCH(2,1/('CONTROLE CRONOG'!G8:Q8<>""))),""),"",IFERROR(INDEX('CONTROLE CRONOG'!G8:Q8,MATCH(2,1/('CONTROLE CRONOG'!G8:Q8<>""))),""))} | S8: =_xlfn.XLOOKUP(TB_INTEGRADA[[#This Row],[Nº SS]],'CONTROLE CRONOG'!B:B,'CONTROLE CRONOG'!T:T,"",0,-1) -> PENDENTE | T8: =IF(TB_INTEGRADA[[#This Row],[STATUS DEMANDA]]="ON HOLD","ON HOLD",IF(TB_INTEGRADA[[#This Row],[STATUS DEMANDA]]="CANCELADA","CANCELADA",IF(TB_INTEGRADA[[#This Row],[DATA APROV. (CR)]]=0,"FISCALIZ.",IF(TB_INTEGRADA[[#This Row],[DATA APROV. (CR)]]="N/A","APROVADO",IF(TB_INTEGRADA[[#This Row],[REVISÃO (CR)]]="","",_xlfn.XLOOKUP(TB_INTEGRADA[[#This Row],[Nº SS]],'CONTROLE CRONOG'!B:B,'CONTROLE CRONOG'!V:V,"",0,1)))))) | X8: =IFERROR(TB_INTEGRADA[[#This Row],[TÉRM. TD]]-TB_INTEGRADA[[#This Row],[TÉRMINO LB]],0) -> 0 | AB8: =IFERROR(TB_INTEGRADA[[#This Row],[REAL (%)]]-TB_INTEGRADA[[#This Row],[PREV (%)]],0) -> 0 | AF8: =IF(TB_INTEGRADA[[#This Row],[TOMADOR]]="EDIVIT",TB_INTEGRADA[[#This Row],[ORÇ DIG]]*1.38,IF(TB_INTEGRADA[[#This Row],[TOMADOR]]="UTGC",TB_INTEGRADA[[#This Row],[ORÇ DIG]]*1.47,IF(TB_INTEGRADA[[#This Row],[TOMADOR]]="TIMS",TB_INTEGRADA[[#This Row],[ORÇ DIG]]*1.34,IF(TB_INTEGRADA[[#This Row],[TOMADOR]]="UTGSUL",TB_INTEGRADA[[#This Row],[ORÇ DIG]]*1.37,IF(TB_INTEGRADA[[#This Row],[TOMADOR]]="REGAP",TB_INTEGRADA[[#This Row],[ORÇ DIG]]*1.36,IF(TB_INTEGRADA[[#This Row],[TOMADOR]]="UTEIBI",TB_INTEGRADA[[#This Row],[ORÇ DIG]]*1.5,"S/TOMADOR")))))) -> 0 | AH8: =SUMIFS(Tb_HhPLAN[Hh DISC],Tb_HhPLAN[SS],TB_INTEGRADA[[#This Row],[Nº SS]],Tb_HhPLAN[DISCIPLINA],"MEC") -> 0 | AI8: =SUMIFS(Hh_EXE_TOTAL[Hh],Hh_EXE_TOTAL[Nº SS],TB_INTEGRADA[[#This Row],[Nº SS]],Hh_EXE_TOTAL[DISCIPLINA],"MEC") -> 0 | AJ8: =IF(TB_INTEGRADA[[#This Row],[TOMADOR]]="EDIVIT",TB_INTEGRADA[[#This Row],[ORÇ DIG1]]*1.38,IF(TB_INTEGRADA[[#This Row],[TOMADOR]]="UTGC",TB_INTEGRADA[[#This Row],[ORÇ DIG1]]*1.47,IF(TB_INTEGRADA[[#This Row],[TOMADOR]]="TIMS",TB_INTEGRADA[[#This Row],[ORÇ DIG1]]*1.34,IF(TB_INTEGRADA[[#This Row],[TOMADOR]]="UTGSUL",TB_INTEGRADA[[#This Row],[ORÇ DIG1]]*1.37,IF(TB_INTEGRADA[[#This Row],[TOMADOR]]="REGAP",TB_INTEGRADA[[#This Row],[ORÇ DIG1]]*1.36,IF(TB_INTEGRADA[[#This Row],[TOMADOR]]="UTEIBI",TB_INTEGRADA[[#This Row],[ORÇ DIG1]]*1.5,"S/TOMADOR")))))) -> 0 | AL8: =SUMIFS(Tb_HhPLAN[Hh DISC],Tb_HhPLAN[SS],TB_INTEGRADA[[#This Row],[Nº SS]],Tb_HhPLAN[DISCIPLINA],"CIVIL") -> 0 | AM8: =SUMIFS(Hh_EXE_TOTAL[Hh],Hh_EXE_TOTAL[Nº SS],TB_INTEGRADA[[#This Row],[Nº SS]],Hh_EXE_TOTAL[DISCIPLINA],"CIVIL") -> 0 | AN8: =IF(TB_INTEGRADA[[#This Row],[TOMADOR]]="EDIVIT",TB_INTEGRADA[[#This Row],[ORÇ DIG2]]*1.38,IF(TB_INTEGRADA[[#This Row],[TOMADOR]]="UTGC",TB_INTEGRADA[[#This Row],[ORÇ DIG2]]*1.47,IF(TB_INTEGRADA[[#This Row],[TOMADOR]]="TIMS",TB_INTEGRADA[[#This Row],[ORÇ DIG2]]*1.34,IF(TB_INTEGRADA[[#This Row],[TOMADOR]]="UTGSUL",TB_INTEGRADA[[#This Row],[ORÇ DIG2]]*1.37,IF(TB_INTEGRADA[[#This Row],[TOMADOR]]="REGAP",TB_INTEGRADA[[#This Row],[ORÇ DIG2]]*1.36,IF(TB_INTEGRADA[[#This Row],[TOMADOR]]="UTEIBI",TB_INTEGRADA[[#This Row],[ORÇ DIG2]]*1.5,"S/TOMADOR")))))) -> 0 | AP8: =SUMIFS(Tb_HhPLAN[Hh DISC],Tb_HhPLAN[SS],TB_INTEGRADA[[#This Row],[Nº SS]],Tb_HhPLAN[DISCIPLINA],"ELÉT") -> 0 | AQ8: =SUMIFS(Hh_EXE_TOTAL[Hh],Hh_EXE_TOTAL[Nº SS],TB_INTEGRADA[[#This Row],[Nº SS]],Hh_EXE_TOTAL[DISCIPLINA],"ELÉT") -> 0 | AR8: =IF(TB_INTEGRADA[[#This Row],[TOMADOR]]="EDIVIT",TB_INTEGRADA[[#This Row],[ORÇ DIG3]]*1.38,IF(TB_INTEGRADA[[#This Row],[TOMADOR]]="UTGC",TB_INTEGRADA[[#This Row],[ORÇ DIG3]]*1.47,IF(TB_INTEGRADA[[#This Row],[TOMADOR]]="TIMS",TB_INTEGRADA[[#This Row],[ORÇ DIG3]]*1.34,IF(TB_INTEGRADA[[#This Row],[TOMADOR]]="UTGSUL",TB_INTEGRADA[[#This Row],[ORÇ DIG3]]*1.37,IF(TB_INTEGRADA[[#This Row],[TOMADOR]]="REGAP",TB_INTEGRADA[[#This Row],[ORÇ DIG3]]*1.36,IF(TB_INTEGRADA[[#This Row],[TOMADOR]]="UTEIBI",TB_INTEGRADA[[#This Row],[ORÇ DIG3]]*1.5,"S/TOMADOR")))))) -> 0 | AT8: =SUMIFS(Tb_HhPLAN[Hh DISC],Tb_HhPLAN[SS],TB_INTEGRADA[[#This Row],[Nº SS]],Tb_HhPLAN[DISCIPLINA],"PINT") -> 0 | AU8: =SUMIFS(Hh_EXE_TOTAL[Hh],Hh_EXE_TOTAL[Nº SS],TB_INTEGRADA[[#This Row],[Nº SS]],Hh_EXE_TOTAL[DISCIPLINA],"PINT") -> 0 | AV8: =TB_INTEGRADA[[#This Row],[ORÇADO]]+TB_INTEGRADA[[#This Row],[ORÇADO1]]+TB_INTEGRADA[[#This Row],[ORÇADO2]]+TB_INTEGRADA[[#This Row],[ORÇADO3]] -> 0 | AW8: =TB_INTEGRADA[[#This Row],[PLANEJ]]+TB_INTEGRADA[[#This Row],[PLANEJ1]]+TB_INTEGRADA[[#This Row],[PLANEJ2]]+TB_INTEGRADA[[#This Row],[PLANEJ3]] -> 0 | AX8: =TB_INTEGRADA[[#This Row],[REALIZ]]+TB_INTEGRADA[[#This Row],[REALIZ1]]+TB_INTEGRADA[[#This Row],[REALIZ2]]+TB_INTEGRADA[[#This Row],[REALIZ3]] -> 0 | AZ8: =_xlfn.XLOOKUP(TB_INTEGRADA[[#This Row],[Nº SS]],'CONTROLE EC'!B:B,'CONTROLE EC'!W:W,"",0,1) -> 0 | BA8: =_xlfn.XLOOKUP(TB_INTEGRADA[[#This Row],[Nº SS]],'CONTROLE EC'!B:B,'CONTROLE EC'!X:X,"",0,1) -> 0 | BB8: =_xlfn.XLOOKUP(TB_INTEGRADA[[#This Row],[Nº SS]],'CONTROLE EC'!B:B,'CONTROLE EC'!Y:Y,"",0,1) -> 0
A9: =IF(COUNTIFS($B$5:B9,TB_INTEGRADA[[#This Row],[Nº SS]])<>1,"",COUNTIFS($B$5:B9,TB_INTEGRADA[[#This Row],[Nº SS]])) -> 1 | B9: SS-04/2025 | C9: =_xlfn.XLOOKUP(TB_INTEGRADA[[#This Row],[Nº SS]],'CONTROLE EC'!B:B,'CONTROLE EC'!C:C,"",0,1) -> 24-0651-ES - MONTAGEM DO GALPÃO DA UPGN-2 | D9: =_xlfn.XLOOKUP(TB_INTEGRADA[[#This Row],[Nº SS]],'CONTROLE CRONOG'!B:B,'CONTROLE CRONOG'!D:D,"",0,1) -> SERVIÇO | E9: =_xlfn.XLOOKUP(TB_INTEGRADA[[#This Row],[Nº SS]],'CONTROLE EC'!B:B,'CONTROLE EC'!E:E,"",0,1) -> UTGC | F9: =_xlfn.XLOOKUP(TB_INTEGRADA[[#This Row],[Nº SS]],'CONTROLE EC'!B:B,'CONTROLE EC'!F:F,"",0,1) -> EM ANDAMENTO | G9: =_xlfn.XLOOKUP(TB_INTEGRADA[[#This Row],[Nº SS]],'CONTROLE EC'!B:B,'CONTROLE EC'!R:R,"",0,1) -> REV.05 | H9: =IF(TB_INTEGRADA[[#This Row],[REVISÃO (EC)]]="","",_xlfn.XLOOKUP(TB_INTEGRADA[[#This Row],[Nº SS]],'CONTROLE EC'!B:B,'CONTROLE EC'!S:S,"",0,1)) -> 45953 | I9: =IF(TB_INTEGRADA[[#This Row],[REVISÃO (EC)]]="","",_xlfn.XLOOKUP(TB_INTEGRADA[[#This Row],[Nº SS]],'CONTROLE EC'!B:B,'CONTROLE EC'!U:U,"",0,1)) -> 45954 | J9: {=IF(TB_INTEGRADA[[#This Row],[DATA ENVIO. (EC)]]=IFERROR(INDEX('CONTROLE EC'!G9:Q9,MATCH(2,1/('CONTROLE EC'!G9:Q9<>""))),""),"",IFERROR(INDEX('CONTROLE EC'!G9:Q9,MATCH(2,1/('CONTROLE EC'!G9:Q9<>""))),""))} | K9: =IF(TB_INTEGRADA[[#This Row],[STATUS DEMANDA]]="NÃO EMITIDA SAMC","S/ EMISSÃO",_xlfn.XLOOKUP(TB_INTEGRADA[[#This Row],[Nº SS]],'CONTROLE EC'!B:B,'CONTROLE EC'!T:T,"",0,-1)) -> ENTREGUE | L9: =IF(TB_INTEGRADA[[#This Row],[STATUS DEMANDA]]="NÃO EMITIDA SAMC","S/ EMISSÃO",IF(TB_INTEGRADA[[#This Row],[STATUS DEMANDA]]="ON HOLD","ON HOLD",IF(TB_INTEGRADA[[#This Row],[STATUS DEMANDA]]="CANCELADA","CANCELADA",IF(TB_INTEGRADA[[#This Row],[DATA APROV. (EC)]]=0,"FISCALIZ.",IF(TB_INTEGRADA[[#This Row],[DATA APROV. (EC)]]="","PEND. FISCALIZ.",IF(TB_INTEGRADA[[#This Row],[DATA APROV. (EC)]]="N/A","APROVADO",IF(TB_INTEGRADA[[#This Row],[REVISÃO (EC)]]="","",_xlfn.XLOOKUP(TB_INTEGRADA[[#This Row],[Nº SS]],'CONTROLE EC'!B:B,'CONTROLE EC'!V:V,"",0,1)))))))) -> APROVADO | M9: {=IFERROR(_xlfn.IFS(TB_INTEGRADA[[#This Row],[STATUS DEMANDA]]="CANCELADA",0,TB_INTEGRADA[[#This Row],[DATA APROV. (EC)]]="",TODAY()-TB_INTEGRADA[[#This Row],[DATA ENVIO. (EC)]],TB_INTEGRADA[[#This Row],[DATA APROV. (EC)]]>=TB_INTEGRADA[[#This Row],[DATA ENVIO. (EC)]],0,TB_INTEGRADA[[#This Row],[DATA ENVIO. (EC)]]="",0,TB_INTEGRADA[[#This Row],[DATA ENVIO. (EC)]]>TB_INTEGRADA[[#This Row],[DATA APROV. (EC)]],TODAY()-TB_INTEGRADA[[#This Row],[DATA ENVIO. (EC)]]),"")} -> 0 | N9: =IF(TB_INTEGRADA[[#This Row],[STATUS DEMANDA]]="NÃO EMITIDA SAMC","S/ EMISSÃO",IF(TB_INTEGRADA[[#This Row],[STATUS DEMANDA]]="ON HOLD","ON HOLD",IF(F9="CANCELADA","CANCELADA",IF(L9="REPROVADO","EM PLANEJ.",IF(K9<>"ENTREGUE","EM PLANEJ.",IF(H9="","EM PLANEJ.",IF(I9="","FISCALIZ.",IF(M9<0,"EM PLANEJ.",IF(TB_INTEGRADA[[#This Row],[DATA APROV. (EC)]]>=TB_INTEGRADA[[#This Row],[DATA ENVIO. (EC)]],"RETORNO OK","FISCALIZ."))))))))) -> RETORNO OK | O9: =_xlfn.XLOOKUP(TB_INTEGRADA[[#This Row],[Nº SS]],'CONTROLE CRONOG'!B:B,'CONTROLE CRONOG'!R:R,"",0,1) -> REV.03 | P9: =IF(TB_INTEGRADA[[#This Row],[REVISÃO (CR)]]="","",_xlfn.XLOOKUP(TB_INTEGRADA[[#This Row],[Nº SS]],'CONTROLE CRONOG'!B:B,'CONTROLE CRONOG'!S:S,"",0,1)) -> 45953 | Q9: =IF(TB_INTEGRADA[[#This Row],[REVISÃO (CR)]]="","",_xlfn.XLOOKUP(TB_INTEGRADA[[#This Row],[Nº SS]],'CONTROLE CRONOG'!B:B,'CONTROLE CRONOG'!U:U,"",0,1)) -> 45953 | R9: {=IF(TB_INTEGRADA[[#This Row],[DATA ENVIO. (CR)]]=IFERROR(INDEX('CONTROLE CRONOG'!G9:Q9,MATCH(2,1/('CONTROLE CRONOG'!G9:Q9<>""))),""),"",IFERROR(INDEX('CONTROLE CRONOG'!G9:Q9,MATCH(2,1/('CONTROLE CRONOG'!G9:Q9<>""))),""))} | S9: =_xlfn.XLOOKUP(TB_INTEGRADA[[#This Row],[Nº SS]],'CONTROLE CRONOG'!B:B,'CONTROLE CRONOG'!T:T,"",0,-1) -> ENTREGUE | T9: =IF(TB_INTEGRADA[[#This Row],[STATUS DEMANDA]]="ON HOLD","ON HOLD",IF(TB_INTEGRADA[[#This Row],[STATUS DEMANDA]]="CANCELADA","CANCELADA",IF(TB_INTEGRADA[[#This Row],[DATA APROV. (CR)]]=0,"FISCALIZ.",IF(TB_INTEGRADA[[#This Row],[DATA APROV. (CR)]]="N/A","APROVADO",IF(TB_INTEGRADA[[#This Row],[REVISÃO (CR)]]="","",_xlfn.XLOOKUP(TB_INTEGRADA[[#This Row],[Nº SS]],'CONTROLE CRONOG'!B:B,'CONTROLE CRONOG'!V:V,"",0,1)))))) -> APROVADO | V9: 46197 | W9: 46198 | X9: =IFERROR(TB_INTEGRADA[[#This Row],[TÉRM. TD]]-TB_INTEGRADA[[#This Row],[TÉRMINO LB]],0) -> 1 | Y9: 0.4484 | Z9: 0.4219 | AA9: -0.0152 | AB9: =IFERROR(TB_INTEGRADA[[#This Row],[REAL (%)]]-TB_INTEGRADA[[#This Row],[PREV (%)]],0) -> -0.0265 | AC9: 6 | AD9: 16 | AF9: =IF(TB_INTEGRADA[[#This Row],[TOMADOR]]="EDIVIT",TB_INTEGRADA[[#This Row],[ORÇ DIG]]*1.38,IF(TB_INTEGRADA[[#This Row],[TOMADOR]]="UTGC",TB_INTEGRADA[[#This Row],[ORÇ DIG]]*1.47,IF(TB_INTEGRADA[[#This Row],[TOMADOR]]="TIMS",TB_INTEGRADA[[#This Row],[ORÇ DIG]]*1.34,IF(TB_INTEGRADA[[#This Row],[TOMADOR]]="UTGSUL",TB_INTEGRADA[[#This Row],[ORÇ DIG]]*1.37,IF(TB_INTEGRADA[[#This Row],[TOMADOR]]="REGAP",TB_INTEGRADA[[#This Row],[ORÇ DIG]]*1.36,IF(TB_INTEGRADA[[#This Row],[TOMADOR]]="UTEIBI",TB_INTEGRADA[[#This Row],[ORÇ DIG]]*1.5,"S/TOMADOR")))))) -> 8862.4242 | AG9: 6028.86 | AH9: =SUMIFS(Tb_HhPLAN[Hh DISC],Tb_HhPLAN[SS],TB_INTEGRADA[[#This Row],[Nº SS]],Tb_HhPLAN[DISCIPLINA],"MEC") -> 5356.0441 | AI9: =SUMIFS(Hh_EXE_TOTAL[Hh],Hh_EXE_TOTAL[Nº SS],TB_INTEGRADA[[#This Row],[Nº SS]],Hh_EXE_TOTAL[DISCIPLINA],"MEC") -> 4618.2781 | AJ9: =IF(TB_INTEGRADA[[#This Row],[TOMADOR]]="EDIVIT",TB_INTEGRADA[[#This Row],[ORÇ DIG1]]*1.38,IF(TB_INTEGRADA[[#This Row],[TOMADOR]]="UTGC",TB_INTEGRADA[[#This Row],[ORÇ DIG1]]*1.47,IF(TB_INTEGRADA[[#This Row],[TOMADOR]]="TIMS",TB_INTEGRADA[[#This Row],[ORÇ DIG1]]*1.34,IF(TB_INTEGRADA[[#This Row],[TOMADOR]]="UTGSUL",TB_INTEGRADA[[#This Row],[ORÇ DIG1]]*1.37,IF(TB_INTEGRADA[[#This Row],[TOMADOR]]="REGAP",TB_INTEGRADA[[#This Row],[ORÇ DIG1]]*1.36,IF(TB_INTEGRADA[[#This Row],[TOMADOR]]="UTEIBI",TB_INTEGRADA[[#This Row],[ORÇ DIG1]]*1.5,"S/TOMADOR")))))) -> 92.4483 | AK9: 62.89 | AL9: =SUMIFS(Tb_HhPLAN[Hh DISC],Tb_HhPLAN[SS],TB_INTEGRADA[[#This Row],[Nº SS]],Tb_HhPLAN[DISCIPLINA],"CIVIL") -> 641.89229 | AM9: =SUMIFS(Hh_EXE_TOTAL[Hh],Hh_EXE_TOTAL[Nº SS],TB_INTEGRADA[[#This Row],[Nº SS]],Hh_EXE_TOTAL[DISCIPLINA],"CIVIL") -> 70.278146 | AN9: =IF(TB_INTEGRADA[[#This Row],[TOMADOR]]="EDIVIT",TB_INTEGRADA[[#This Row],[ORÇ DIG2]]*1.38,IF(TB_INTEGRADA[[#This Row],[TOMADOR]]="UTGC",TB_INTEGRADA[[#This Row],[ORÇ DIG2]]*1.47,IF(TB_INTEGRADA[[#This Row],[TOMADOR]]="TIMS",TB_INTEGRADA[[#This Row],[ORÇ DIG2]]*1.34,IF(TB_INTEGRADA[[#This Row],[TOMADOR]]="UTGSUL",TB_INTEGRADA[[#This Row],[ORÇ DIG2]]*1.37,IF(TB_INTEGRADA[[#This Row],[TOMADOR]]="REGAP",TB_INTEGRADA[[#This Row],[ORÇ DIG2]]*1.36,IF(TB_INTEGRADA[[#This Row],[TOMADOR]]="UTEIBI",TB_INTEGRADA[[#This Row],[ORÇ DIG2]]*1.5,"S/TOMADOR")))))) -> 3410.2383 | AO9: 2319.89 | AP9: =SUMIFS(Tb_HhPLAN[Hh DISC],Tb_HhPLAN[SS],TB_INTEGRADA[[#This Row],[Nº SS]],Tb_HhPLAN[DISCIPLINA],"ELÉT") -> 671.06922 | AQ9: =SUMIFS(Hh_EXE_TOTAL[Hh],Hh_EXE_TOTAL[Nº SS],TB_INTEGRADA[[#This Row],[Nº SS]],Hh_EXE_TOTAL[DISCIPLINA],"ELÉT") -> 421.66887 | AR9: =IF(TB_INTEGRADA[[#This Row],[TOMADOR]]="EDIVIT",TB_INTEGRADA[[#This Row],[ORÇ DIG3]]*1.38,IF(TB_INTEGRADA[[#This Row],[TOMADOR]]="UTGC",TB_INTEGRADA[[#This Row],[ORÇ DIG3]]*1.47,IF(TB_INTEGRADA[[#This Row],[TOMADOR]]="TIMS",TB_INTEGRADA[[#This Row],[ORÇ DIG3]]*1.34,IF(TB_INTEGRADA[[#This Row],[TOMADOR]]="UTGSUL",TB_INTEGRADA[[#This Row],[ORÇ DIG3]]*1.37,IF(TB_INTEGRADA[[#This Row],[TOMADOR]]="REGAP",TB_INTEGRADA[[#This Row],[ORÇ DIG3]]*1.36,IF(TB_INTEGRADA[[#This Row],[TOMADOR]]="UTEIBI",TB_INTEGRADA[[#This Row],[ORÇ DIG3]]*1.5,"S/TOMADOR")))))) -> 10374.54 | AS9: 7057.51 | AT9: =SUMIFS(Tb_HhPLAN[Hh DISC],Tb_HhPLAN[SS],TB_INTEGRADA[[#This Row],[Nº SS]],Tb_HhPLAN[DISCIPLINA],"PINT") -> 2447.2144 | AU9: =SUMIFS(Hh_EXE_TOTAL[Hh],Hh_EXE_TOTAL[Nº SS],TB_INTEGRADA[[#This Row],[Nº SS]],Hh_EXE_TOTAL[DISCIPLINA],"PINT") -> 953.77483 | AV9: =TB_INTEGRADA[[#This Row],[ORÇADO]]+TB_INTEGRADA[[#This Row],[ORÇADO1]]+TB_INTEGRADA[[#This Row],[ORÇADO2]]+TB_INTEGRADA[[#This Row],[ORÇADO3]] -> 22739.65 | AW9: =TB_INTEGRADA[[#This Row],[PLANEJ]]+TB_INTEGRADA[[#This Row],[PLANEJ1]]+TB_INTEGRADA[[#This Row],[PLANEJ2]]+TB_INTEGRADA[[#This Row],[PLANEJ3]] -> 9116.22 | AX9: =TB_INTEGRADA[[#This Row],[REALIZ]]+TB_INTEGRADA[[#This Row],[REALIZ1]]+TB_INTEGRADA[[#This Row],[REALIZ2]]+TB_INTEGRADA[[#This Row],[REALIZ3]] -> 6064 | AY9: =IFERROR(TB_INTEGRADA[[#This Row],[REALIZ4]]/TB_INTEGRADA[[#This Row],[ORÇADO4]],"") -> 0.26667077 | AZ9: =_xlfn.XLOOKUP(TB_INTEGRADA[[#This Row],[Nº SS]],'CONTROLE EC'!B:B,'CONTROLE EC'!W:W,"",0,1) -> 9201249.3 | BA9: =_xlfn.XLOOKUP(TB_INTEGRADA[[#This Row],[Nº SS]],'CONTROLE EC'!B:B,'CONTROLE EC'!X:X,"",0,1) -> 4922668.3 | BB9: =_xlfn.XLOOKUP(TB_INTEGRADA[[#This Row],[Nº SS]],'CONTROLE EC'!B:B,'CONTROLE EC'!Y:Y,"",0,1) -> 4278581
A10: =IF(COUNTIFS($B$5:B10,TB_INTEGRADA[[#This Row],[Nº SS]])<>1,"",COUNTIFS($B$5:B10,TB_INTEGRADA[[#This Row],[Nº SS]])) -> 1 | B10: SS-05/2025 | C10: =_xlfn.XLOOKUP(TB_INTEGRADA[[#This Row],[Nº SS]],'CONTROLE EC'!B:B,'CONTROLE EC'!C:C,"",0,1) -> 23-0706-ES - MANUTENÇÃO DO GALPÃO SECGN | D10: =_xlfn.XLOOKUP(TB_INTEGRADA[[#This Row],[Nº SS]],'CONTROLE CRONOG'!B:B,'CONTROLE CRONOG'!D:D,"",0,1) -> SERVIÇO | E10: =_xlfn.XLOOKUP(TB_INTEGRADA[[#This Row],[Nº SS]],'CONTROLE EC'!B:B,'CONTROLE EC'!E:E,"",0,1) -> UTGC | F10: =_xlfn.XLOOKUP(TB_INTEGRADA[[#This Row],[Nº SS]],'CONTROLE EC'!B:B,'CONTROLE EC'!F:F,"",0,1) -> CONCLUÍDA | G10: =_xlfn.XLOOKUP(TB_INTEGRADA[[#This Row],[Nº SS]],'CONTROLE EC'!B:B,'CONTROLE EC'!R:R,"",0,1) -> REV.03 | H10: =IF(TB_INTEGRADA[[#This Row],[REVISÃO (EC)]]="","",_xlfn.XLOOKUP(TB_INTEGRADA[[#This Row],[Nº SS]],'CONTROLE EC'!B:B,'CONTROLE EC'!S:S,"",0,1)) -> 45932 | I10: =IF(TB_INTEGRADA[[#This Row],[REVISÃO (EC)]]="","",_xlfn.XLOOKUP(TB_INTEGRADA[[#This Row],[Nº SS]],'CONTROLE EC'!B:B,'CONTROLE EC'!U:U,"",0,1)) -> 45932 | J10: {=IF(TB_INTEGRADA[[#This Row],[DATA ENVIO. (EC)]]=IFERROR(INDEX('CONTROLE EC'!G10:Q10,MATCH(2,1/('CONTROLE EC'!G10:Q10<>""))),""),"",IFERROR(INDEX('CONTROLE EC'!G10:Q10,MATCH(2,1/('CONTROLE EC'!G10:Q10<>""))),""))} | K10: =IF(TB_INTEGRADA[[#This Row],[STATUS DEMANDA]]="NÃO EMITIDA SAMC","S/ EMISSÃO",_xlfn.XLOOKUP(TB_INTEGRADA[[#This Row],[Nº SS]],'CONTROLE EC'!B:B,'CONTROLE EC'!T:T,"",0,-1)) -> ENTREGUE | L10: =IF(TB_INTEGRADA[[#This Row],[STATUS DEMANDA]]="NÃO EMITIDA SAMC","S/ EMISSÃO",IF(TB_INTEGRADA[[#This Row],[STATUS DEMANDA]]="ON HOLD","ON HOLD",IF(TB_INTEGRADA[[#This Row],[STATUS DEMANDA]]="CANCELADA","CANCELADA",IF(TB_INTEGRADA[[#This Row],[DATA APROV. (EC)]]=0,"FISCALIZ.",IF(TB_INTEGRADA[[#This Row],[DATA APROV. (EC)]]="","PEND. FISCALIZ.",IF(TB_INTEGRADA[[#This Row],[DATA APROV. (EC)]]="N/A","APROVADO",IF(TB_INTEGRADA[[#This Row],[REVISÃO (EC)]]="","",_xlfn.XLOOKUP(TB_INTEGRADA[[#This Row],[Nº SS]],'CONTROLE EC'!B:B,'CONTROLE EC'!V:V,"",0,1)))))))) -> APROVADO | M10: {=IFERROR(_xlfn.IFS(TB_INTEGRADA[[#This Row],[STATUS DEMANDA]]="CANCELADA",0,TB_INTEGRADA[[#This Row],[DATA APROV. (EC)]]="",TODAY()-TB_INTEGRADA[[#This Row],[DATA ENVIO. (EC)]],TB_INTEGRADA[[#This Row],[DATA APROV. (EC)]]>=TB_INTEGRADA[[#This Row],[DATA ENVIO. (EC)]],0,TB_INTEGRADA[[#This Row],[DATA ENVIO. (EC)]]="",0,TB_INTEGRADA[[#This Row],[DATA ENVIO. (EC)]]>TB_INTEGRADA[[#This Row],[DATA APROV. (EC)]],TODAY()-TB_INTEGRADA[[#This Row],[DATA ENVIO. (EC)]]),"")} -> 0 | N10: =IF(TB_INTEGRADA[[#This Row],[STATUS DEMANDA]]="NÃO EMITIDA SAMC","S/ EMISSÃO",IF(TB_INTEGRADA[[#This Row],[STATUS DEMANDA]]="ON HOLD","ON HOLD",IF(F10="CANCELADA","CANCELADA",IF(L10="REPROVADO","EM PLANEJ.",IF(K10<>"ENTREGUE","EM PLANEJ.",IF(H10="","EM PLANEJ.",IF(I10="","FISCALIZ.",IF(M10<0,"EM PLANEJ.",IF(TB_INTEGRADA[[#This Row],[DATA APROV. (EC)]]>=TB_INTEGRADA[[#This Row],[DATA ENVIO. (EC)]],"RETORNO OK","FISCALIZ."))))))))) -> RETORNO OK | O10: =_xlfn.XLOOKUP(TB_INTEGRADA[[#This Row],[Nº SS]],'CONTROLE CRONOG'!B:B,'CONTROLE CRONOG'!R:R,"",0,1) -> REV.01 | P10: =IF(TB_INTEGRADA[[#This Row],[REVISÃO (CR)]]="","",_xlfn.XLOOKUP(TB_INTEGRADA[[#This Row],[Nº SS]],'CONTROLE CRONOG'!B:B,'CONTROLE CRONOG'!S:S,"",0,1)) -> 45925 | Q10: =IF(TB_INTEGRADA[[#This Row],[REVISÃO (CR)]]="","",_xlfn.XLOOKUP(TB_INTEGRADA[[#This Row],[Nº SS]],'CONTROLE CRONOG'!B:B,'CONTROLE CRONOG'!U:U,"",0,1)) -> 45925 | R10: {=IF(TB_INTEGRADA[[#This Row],[DATA ENVIO. (CR)]]=IFERROR(INDEX('CONTROLE CRONOG'!G10:Q10,MATCH(2,1/('CONTROLE CRONOG'!G10:Q10<>""))),""),"",IFERROR(INDEX('CONTROLE CRONOG'!G10:Q10,MATCH(2,1/('CONTROLE CRONOG'!G10:Q10<>""))),""))} | S10: =_xlfn.XLOOKUP(TB_INTEGRADA[[#This Row],[Nº SS]],'CONTROLE CRONOG'!B:B,'CONTROLE CRONOG'!T:T,"",0,-1) -> ENTREGUE | T10: =IF(TB_INTEGRADA[[#This Row],[STATUS DEMANDA]]="ON HOLD","ON HOLD",IF(TB_INTEGRADA[[#This Row],[STATUS DEMANDA]]="CANCELADA","CANCELADA",IF(TB_INTEGRADA[[#This Row],[DATA APROV. (CR)]]=0,"FISCALIZ.",IF(TB_INTEGRADA[[#This Row],[DATA APROV. (CR)]]="N/A","APROVADO",IF(TB_INTEGRADA[[#This Row],[REVISÃO (CR)]]="","",_xlfn.XLOOKUP(TB_INTEGRADA[[#This Row],[Nº SS]],'CONTROLE CRONOG'!B:B,'CONTROLE CRONOG'!V:V,"",0,1)))))) -> APROVADO | V10: 46009 | W10: 46059 | X10: =IFERROR(TB_INTEGRADA[[#This Row],[TÉRM. TD]]-TB_INTEGRADA[[#This Row],[TÉRMINO LB]],0) -> 50 | Y10: 1 | Z10: 1 | AA10: 0 | AB10: =IFERROR(TB_INTEGRADA[[#This Row],[REAL (%)]]-TB_INTEGRADA[[#This Row],[PREV (%)]],0) -> 0 | AC10: 0 | AD10: 0 | AF10: =IF(TB_INTEGRADA[[#This Row],[TOMADOR]]="EDIVIT",TB_INTEGRADA[[#This Row],[ORÇ DIG]]*1.38,IF(TB_INTEGRADA[[#This Row],[TOMADOR]]="UTGC",TB_INTEGRADA[[#This Row],[ORÇ DIG]]*1.47,IF(TB_INTEGRADA[[#This Row],[TOMADOR]]="TIMS",TB_INTEGRADA[[#This Row],[ORÇ DIG]]*1.34,IF(TB_INTEGRADA[[#This Row],[TOMADOR]]="UTGSUL",TB_INTEGRADA[[#This Row],[ORÇ DIG]]*1.37,IF(TB_INTEGRADA[[#This Row],[TOMADOR]]="REGAP",TB_INTEGRADA[[#This Row],[ORÇ DIG]]*1.36,IF(TB_INTEGRADA[[#This Row],[TOMADOR]]="UTEIBI",TB_INTEGRADA[[#This Row],[ORÇ DIG]]*1.5,"S/TOMADOR")))))) -> 1119.3168 | AG10: 761.44 | AH10: =SUMIFS(Tb_HhPLAN[Hh DISC],Tb_HhPLAN[SS],TB_INTEGRADA[[#This Row],[Nº SS]],Tb_HhPLAN[DISCIPLINA],"MEC") -> 1392 | AI10: =SUMIFS(Hh_EXE_TOTAL[Hh],Hh_EXE_TOTAL[Nº SS],TB_INTEGRADA[[#This Row],[Nº SS]],Hh_EXE_TOTAL[DISCIPLINA],"MEC") -> 3037.0892 | AJ10: =IF(TB_INTEGRADA[[#This Row],[TOMADOR]]="EDIVIT",TB_INTEGRADA[[#This Row],[ORÇ DIG1]]*1.38,IF(TB_INTEGRADA[[#This Row],[TOMADOR]]="UTGC",TB_INTEGRADA[[#This Row],[ORÇ DIG1]]*1.47,IF(TB_INTEGRADA[[#This Row],[TOMADOR]]="TIMS",TB_INTEGRADA[[#This Row],[ORÇ DIG1]]*1.34,IF(TB_INTEGRADA[[#This Row],[TOMADOR]]="UTGSUL",TB_INTEGRADA[[#This Row],[ORÇ DIG1]]*1.37,IF(TB_INTEGRADA[[#This Row],[TOMADOR]]="REGAP",TB_INTEGRADA[[#This Row],[ORÇ DIG1]]*1.36,IF(TB_INTEGRADA[[#This Row],[TOMADOR]]="UTEIBI",TB_INTEGRADA[[#This Row],[ORÇ DIG1]]*1.5,"S/TOMADOR")))))) -> 0 | AK10: 0 | AL10: =SUMIFS(Tb_HhPLAN[Hh DISC],Tb_HhPLAN[SS],TB_INTEGRADA[[#This Row],[Nº SS]],Tb_HhPLAN[DISCIPLINA],"CIVIL") -> 0 | AM10: =SUMIFS(Hh_EXE_TOTAL[Hh],Hh_EXE_TOTAL[Nº SS],TB_INTEGRADA[[#This Row],[Nº SS]],Hh_EXE_TOTAL[DISCIPLINA],"CIVIL") -> 38.322892 | AN10: =IF(TB_INTEGRADA[[#This Row],[TOMADOR]]="EDIVIT",TB_INTEGRADA[[#This Row],[ORÇ DIG2]]*1.38,IF(TB_INTEGRADA[[#This Row],[TOMADOR]]="UTGC",TB_INTEGRADA[[#This Row],[ORÇ DIG2]]*1.47,IF(TB_INTEGRADA[[#This Row],[TOMADOR]]="TIMS",TB_INTEGRADA[[#This Row],[ORÇ DIG2]]*1.34,IF(TB_INTEGRADA[[#This Row],[TOMADOR]]="UTGSUL",TB_INTEGRADA[[#This Row],[ORÇ DIG2]]*1.37,IF(TB_INTEGRADA[[#This Row],[TOMADOR]]="REGAP",TB_INTEGRADA[[#This Row],[ORÇ DIG2]]*1.36,IF(TB_INTEGRADA[[#This Row],[TOMADOR]]="UTEIBI",TB_INTEGRADA[[#This Row],[ORÇ DIG2]]*1.5,"S/TOMADOR")))))) -> 1160.124 | AO10: 789.2 | AP10: =SUMIFS(Tb_HhPLAN[Hh DISC],Tb_HhPLAN[SS],TB_INTEGRADA[[#This Row],[Nº SS]],Tb_HhPLAN[DISCIPLINA],"ELÉT") -> 264 | AQ10: =SUMIFS(Hh_EXE_TOTAL[Hh],Hh_EXE_TOTAL[Nº SS],TB_INTEGRADA[[#This Row],[Nº SS]],Hh_EXE_TOTAL[DISCIPLINA],"ELÉT") -> 584.4241 | AR10: =IF(TB_INTEGRADA[[#This Row],[TOMADOR]]="EDIVIT",TB_INTEGRADA[[#This Row],[ORÇ DIG3]]*1.38,IF(TB_INTEGRADA[[#This Row],[TOMADOR]]="UTGC",TB_INTEGRADA[[#This Row],[ORÇ DIG3]]*1.47,IF(TB_INTEGRADA[[#This Row],[TOMADOR]]="TIMS",TB_INTEGRADA[[#This Row],[ORÇ DIG3]]*1.34,IF(TB_INTEGRADA[[#This Row],[TOMADOR]]="UTGSUL",TB_INTEGRADA[[#This Row],[ORÇ DIG3]]*1.37,IF(TB_INTEGRADA[[#This Row],[TOMADOR]]="REGAP",TB_INTEGRADA[[#This Row],[ORÇ DIG3]]*1.36,IF(TB_INTEGRADA[[#This Row],[TOMADOR]]="UTEIBI",TB_INTEGRADA[[#This Row],[ORÇ DIG3]]*1.5,"S/TOMADOR")))))) -> 552.9993 | AS10: 376.19 | AT10: =SUMIFS(Tb_HhPLAN[Hh DISC],Tb_HhPLAN[SS],TB_INTEGRADA[[#This Row],[Nº SS]],Tb_HhPLAN[DISCIPLINA],"PINT") -> 384 | AU10: =SUMIFS(Hh_EXE_TOTAL[Hh],Hh_EXE_TOTAL[Nº SS],TB_INTEGRADA[[#This Row],[Nº SS]],Hh_EXE_TOTAL[DISCIPLINA],"PINT") -> 316.16386 | AV10: =TB_INTEGRADA[[#This Row],[ORÇADO]]+TB_INTEGRADA[[#This Row],[ORÇADO1]]+TB_INTEGRADA[[#This Row],[ORÇADO2]]+TB_INTEGRADA[[#This Row],[ORÇADO3]] -> 2832.4401 | AW10: =TB_INTEGRADA[[#This Row],[PLANEJ]]+TB_INTEGRADA[[#This Row],[PLANEJ1]]+TB_INTEGRADA[[#This Row],[PLANEJ2]]+TB_INTEGRADA[[#This Row],[PLANEJ3]] -> 2040 | AX10: =TB_INTEGRADA[[#This Row],[REALIZ]]+TB_INTEGRADA[[#This Row],[REALIZ1]]+TB_INTEGRADA[[#This Row],[REALIZ2]]+TB_INTEGRADA[[#This Row],[REALIZ3]] -> 3976 | AY10: =IFERROR(TB_INTEGRADA[[#This Row],[REALIZ4]]/TB_INTEGRADA[[#This Row],[ORÇADO4]],"") -> 1.4037367 | AZ10: =_xlfn.XLOOKUP(TB_INTEGRADA[[#This Row],[Nº SS]],'CONTROLE EC'!B:B,'CONTROLE EC'!W:W,"",0,1) -> 857462.22 | BA10: =_xlfn.XLOOKUP(TB_INTEGRADA[[#This Row],[Nº SS]],'CONTROLE EC'!B:B,'CONTROLE EC'!X:X,"",0,1) -> 857462.22 | BB10: =_xlfn.XLOOKUP(TB_INTEGRADA[[#This Row],[Nº SS]],'CONTROLE EC'!B:B,'CONTROLE EC'!Y:Y,"",0,1) -> 0
A11: =IF(COUNTIFS($B$5:B11,TB_INTEGRADA[[#This Row],[Nº SS]])<>1,"",COUNTIFS($B$5:B11,TB_INTEGRADA[[#This Row],[Nº SS]])) -> 1 | B11: SS-06/2025 | C11: =_xlfn.XLOOKUP(TB_INTEGRADA[[#This Row],[Nº SS]],'CONTROLE EC'!B:B,'CONTROLE EC'!C:C,"",0,1) -> 23-0803-ES - MANUTENÇÃO DO GALPÃO K-14 | D11: =_xlfn.XLOOKUP(TB_INTEGRADA[[#This Row],[Nº SS]],'CONTROLE CRONOG'!B:B,'CONTROLE CRONOG'!D:D,"",0,1) -> SERVIÇO | E11: =_xlfn.XLOOKUP(TB_INTEGRADA[[#This Row],[Nº SS]],'CONTROLE EC'!B:B,'CONTROLE EC'!E:E,"",0,1) -> UTGC | F11: =_xlfn.XLOOKUP(TB_INTEGRADA[[#This Row],[Nº SS]],'CONTROLE EC'!B:B,'CONTROLE EC'!F:F,"",0,1) -> CONCLUÍDA | G11: =_xlfn.XLOOKUP(TB_INTEGRADA[[#This Row],[Nº SS]],'CONTROLE EC'!B:B,'CONTROLE EC'!R:R,"",0,1) -> REV.04 | H11: =IF(TB_INTEGRADA[[#This Row],[REVISÃO (EC)]]="","",_xlfn.XLOOKUP(TB_INTEGRADA[[#This Row],[Nº SS]],'CONTROLE EC'!B:B,'CONTROLE EC'!S:S,"",0,1)) -> 45947 | I11: =IF(TB_INTEGRADA[[#This Row],[REVISÃO (EC)]]="","",_xlfn.XLOOKUP(TB_INTEGRADA[[#This Row],[Nº SS]],'CONTROLE EC'!B:B,'CONTROLE EC'!U:U,"",0,1)) -> 45947 | J11: {=IF(TB_INTEGRADA[[#This Row],[DATA ENVIO. (EC)]]=IFERROR(INDEX('CONTROLE EC'!G11:Q11,MATCH(2,1/('CONTROLE EC'!G11:Q11<>""))),""),"",IFERROR(INDEX('CONTROLE EC'!G11:Q11,MATCH(2,1/('CONTROLE EC'!G11:Q11<>""))),""))} | K11: =IF(TB_INTEGRADA[[#This Row],[STATUS DEMANDA]]="NÃO EMITIDA SAMC","S/ EMISSÃO",_xlfn.XLOOKUP(TB_INTEGRADA[[#This Row],[Nº SS]],'CONTROLE EC'!B:B,'CONTROLE EC'!T:T,"",0,-1)) -> ENTREGUE | L11: =IF(TB_INTEGRADA[[#This Row],[STATUS DEMANDA]]="NÃO EMITIDA SAMC","S/ EMISSÃO",IF(TB_INTEGRADA[[#This Row],[STATUS DEMANDA]]="ON HOLD","ON HOLD",IF(TB_INTEGRADA[[#This Row],[STATUS DEMANDA]]="CANCELADA","CANCELADA",IF(TB_INTEGRADA[[#This Row],[DATA APROV. (EC)]]=0,"FISCALIZ.",IF(TB_INTEGRADA[[#This Row],[DATA APROV. (EC)]]="","PEND. FISCALIZ.",IF(TB_INTEGRADA[[#This Row],[DATA APROV. (EC)]]="N/A","APROVADO",IF(TB_INTEGRADA[[#This Row],[REVISÃO (EC)]]="","",_xlfn.XLOOKUP(TB_INTEGRADA[[#This Row],[Nº SS]],'CONTROLE EC'!B:B,'CONTROLE EC'!V:V,"",0,1)))))))) -> APROVADO | M11: {=IFERROR(_xlfn.IFS(TB_INTEGRADA[[#This Row],[STATUS DEMANDA]]="CANCELADA",0,TB_INTEGRADA[[#This Row],[DATA APROV. (EC)]]="",TODAY()-TB_INTEGRADA[[#This Row],[DATA ENVIO. (EC)]],TB_INTEGRADA[[#This Row],[DATA APROV. (EC)]]>=TB_INTEGRADA[[#This Row],[DATA ENVIO. (EC)]],0,TB_INTEGRADA[[#This Row],[DATA ENVIO. (EC)]]="",0,TB_INTEGRADA[[#This Row],[DATA ENVIO. (EC)]]>TB_INTEGRADA[[#This Row],[DATA APROV. (EC)]],TODAY()-TB_INTEGRADA[[#This Row],[DATA ENVIO. (EC)]]),"")} -> 0 | N11: =IF(TB_INTEGRADA[[#This Row],[STATUS DEMANDA]]="NÃO EMITIDA SAMC","S/ EMISSÃO",IF(TB_INTEGRADA[[#This Row],[STATUS DEMANDA]]="ON HOLD","ON HOLD",IF(F11="CANCELADA","CANCELADA",IF(L11="REPROVADO","EM PLANEJ.",IF(K11<>"ENTREGUE","EM PLANEJ.",IF(H11="","EM PLANEJ.",IF(I11="","FISCALIZ.",IF(M11<0,"EM PLANEJ.",IF(TB_INTEGRADA[[#This Row],[DATA APROV. (EC)]]>=TB_INTEGRADA[[#This Row],[DATA ENVIO. (EC)]],"RETORNO OK","FISCALIZ."))))))))) -> RETORNO OK | O11: =_xlfn.XLOOKUP(TB_INTEGRADA[[#This Row],[Nº SS]],'CONTROLE CRONOG'!B:B,'CONTROLE CRONOG'!R:R,"",0,1) -> REV.03 | P11: =IF(TB_INTEGRADA[[#This Row],[REVISÃO (CR)]]="","",_xlfn.XLOOKUP(TB_INTEGRADA[[#This Row],[Nº SS]],'CONTROLE CRONOG'!B:B,'CONTROLE CRONOG'!S:S,"",0,1)) -> 45952 | Q11: =IF(TB_INTEGRADA[[#This Row],[REVISÃO (CR)]]="","",_xlfn.XLOOKUP(TB_INTEGRADA[[#This Row],[Nº SS]],'CONTROLE CRONOG'!B:B,'CONTROLE CRONOG'!U:U,"",0,1)) -> 45952 | R11: {=IF(TB_INTEGRADA[[#This Row],[DATA ENVIO. (CR)]]=IFERROR(INDEX('CONTROLE CRONOG'!G11:Q11,MATCH(2,1/('CONTROLE CRONOG'!G11:Q11<>""))),""),"",IFERROR(INDEX('CONTROLE CRONOG'!G11:Q11,MATCH(2,1/('CONTROLE CRONOG'!G11:Q11<>""))),""))} | S11: =_xlfn.XLOOKUP(TB_INTEGRADA[[#This Row],[Nº SS]],'CONTROLE CRONOG'!B:B,'CONTROLE CRONOG'!T:T,"",0,-1) -> ENTREGUE | T11: =IF(TB_INTEGRADA[[#This Row],[STATUS DEMANDA]]="ON HOLD","ON HOLD",IF(TB_INTEGRADA[[#This Row],[STATUS DEMANDA]]="CANCELADA","CANCELADA",IF(TB_INTEGRADA[[#This Row],[DATA APROV. (CR)]]=0,"FISCALIZ.",IF(TB_INTEGRADA[[#This Row],[DATA APROV. (CR)]]="N/A","APROVADO",IF(TB_INTEGRADA[[#This Row],[REVISÃO (CR)]]="","",_xlfn.XLOOKUP(TB_INTEGRADA[[#This Row],[Nº SS]],'CONTROLE CRONOG'!B:B,'CONTROLE CRONOG'!V:V,"",0,1)))))) -> APROVADO | V11: 46015 | W11: 46052 | X11: =IFERROR(TB_INTEGRADA[[#This Row],[TÉRM. TD]]-TB_INTEGRADA[[#This Row],[TÉRMINO LB]],0) -> 37 | Y11: 1 | Z11: 1 | AA11: 0 | AB11: =IFERROR(TB_INTEGRADA[[#This Row],[REAL (%)]]-TB_INTEGRADA[[#This Row],[PREV (%)]],0) -> 0 | AC11: 0 | AD11: 0 | AF11: =IF(TB_INTEGRADA[[#This Row],[TOMADOR]]="EDIVIT",TB_INTEGRADA[[#This Row],[ORÇ DIG]]*1.38,IF(TB_INTEGRADA[[#This Row],[TOMADOR]]="UTGC",TB_INTEGRADA[[#This Row],[ORÇ DIG]]*1.47,IF(TB_INTEGRADA[[#This Row],[TOMADOR]]="TIMS",TB_INTEGRADA[[#This Row],[ORÇ DIG]]*1.34,IF(TB_INTEGRADA[[#This Row],[TOMADOR]]="UTGSUL",TB_INTEGRADA[[#This Row],[ORÇ DIG]]*1.37,IF(TB_INTEGRADA[[#This Row],[TOMADOR]]="REGAP",TB_INTEGRADA[[#This Row],[ORÇ DIG]]*1.36,IF(TB_INTEGRADA[[#This Row],[TOMADOR]]="UTEIBI",TB_INTEGRADA[[#This Row],[ORÇ DIG]]*1.5,"S/TOMADOR")))))) -> 957.8373 | AG11: 651.59 | AH11: =SUMIFS(Tb_HhPLAN[Hh DISC],Tb_HhPLAN[SS],TB_INTEGRADA[[#This Row],[Nº SS]],Tb_HhPLAN[DISCIPLINA],"MEC") -> 1240.8547 | AI11: =SUMIFS(Hh_EXE_TOTAL[Hh],Hh_EXE_TOTAL[Nº SS],TB_INTEGRADA[[#This Row],[Nº SS]],Hh_EXE_TOTAL[DISCIPLINA],"MEC") -> 1882.0421 | AJ11: =IF(TB_INTEGRADA[[#This Row],[TOMADOR]]="EDIVIT",TB_INTEGRADA[[#This Row],[ORÇ DIG1]]*1.38,IF(TB_INTEGRADA[[#This Row],[TOMADOR]]="UTGC",TB_INTEGRADA[[#This Row],[ORÇ DIG1]]*1.47,IF(TB_INTEGRADA[[#This Row],[TOMADOR]]="TIMS",TB_INTEGRADA[[#This Row],[ORÇ DIG1]]*1.34,IF(TB_INTEGRADA[[#This Row],[TOMADOR]]="UTGSUL",TB_INTEGRADA[[#This Row],[ORÇ DIG1]]*1.37,IF(TB_INTEGRADA[[#This Row],[TOMADOR]]="REGAP",TB_INTEGRADA[[#This Row],[ORÇ DIG1]]*1.36,IF(TB_INTEGRADA[[#This Row],[TOMADOR]]="UTEIBI",TB_INTEGRADA[[#This Row],[ORÇ DIG1]]*1.5,"S/TOMADOR")))))) -> 0 | AK11: 0 | AL11: =SUMIFS(Tb_HhPLAN[Hh DISC],Tb_HhPLAN[SS],TB_INTEGRADA[[#This Row],[Nº SS]],Tb_HhPLAN[DISCIPLINA],"CIVIL") -> 0 | AM11: =SUMIFS(Hh_EXE_TOTAL[Hh],Hh_EXE_TOTAL[Nº SS],TB_INTEGRADA[[#This Row],[Nº SS]],Hh_EXE_TOTAL[DISCIPLINA],"CIVIL") -> 169.28421 | AN11: =IF(TB_INTEGRADA[[#This Row],[TOMADOR]]="EDIVIT",TB_INTEGRADA[[#This Row],[ORÇ DIG2]]*1.38,IF(TB_INTEGRADA[[#This Row],[TOMADOR]]="UTGC",TB_INTEGRADA[[#This Row],[ORÇ DIG2]]*1.47,IF(TB_INTEGRADA[[#This Row],[TOMADOR]]="TIMS",TB_INTEGRADA[[#This Row],[ORÇ DIG2]]*1.34,IF(TB_INTEGRADA[[#This Row],[TOMADOR]]="UTGSUL",TB_INTEGRADA[[#This Row],[ORÇ DIG2]]*1.37,IF(TB_INTEGRADA[[#This Row],[TOMADOR]]="REGAP",TB_INTEGRADA[[#This Row],[ORÇ DIG2]]*1.36,IF(TB_INTEGRADA[[#This Row],[TOMADOR]]="UTEIBI",TB_INTEGRADA[[#This Row],[ORÇ DIG2]]*1.5,"S/TOMADOR")))))) -> 1795.8402 | AO11: 1221.66 | AP11: =SUMIFS(Tb_HhPLAN[Hh DISC],Tb_HhPLAN[SS],TB_INTEGRADA[[#This Row],[Nº SS]],Tb_HhPLAN[DISCIPLINA],"ELÉT") -> 218.97436 | AQ11: =SUMIFS(Hh_EXE_TOTAL[Hh],Hh_EXE_TOTAL[Nº SS],TB_INTEGRADA[[#This Row],[Nº SS]],Hh_EXE_TOTAL[DISCIPLINA],"ELÉT") -> 876.29474 | AR11: =IF(TB_INTEGRADA[[#This Row],[TOMADOR]]="EDIVIT",TB_INTEGRADA[[#This Row],[ORÇ DIG3]]*1.38,IF(TB_INTEGRADA[[#This Row],[TOMADOR]]="UTGC",TB_INTEGRADA[[#This Row],[ORÇ DIG3]]*1.47,IF(TB_INTEGRADA[[#This Row],[TOMADOR]]="TIMS",TB_INTEGRADA[[#This Row],[ORÇ DIG3]]*1.34,IF(TB_INTEGRADA[[#This Row],[TOMADOR]]="UTGSUL",TB_INTEGRADA[[#This Row],[ORÇ DIG3]]*1.37,IF(TB_INTEGRADA[[#This Row],[TOMADOR]]="REGAP",TB_INTEGRADA[[#This Row],[ORÇ DIG3]]*1.36,IF(TB_INTEGRADA[[#This Row],[TOMADOR]]="UTEIBI",TB_INTEGRADA[[#This Row],[ORÇ DIG3]]*1.5,"S/TOMADOR")))))) -> 413.217 | AS11: 281.1 | AT11: =SUMIFS(Tb_HhPLAN[Hh DISC],Tb_HhPLAN[SS],TB_INTEGRADA[[#This Row],[Nº SS]],Tb_HhPLAN[DISCIPLINA],"PINT") -> 248.17094 | AU11: =SUMIFS(Hh_EXE_TOTAL[Hh],Hh_EXE_TOTAL[Nº SS],TB_INTEGRADA[[#This Row],[Nº SS]],Hh_EXE_TOTAL[DISCIPLINA],"PINT") -> 856.37895 | AV11: =TB_INTEGRADA[[#This Row],[ORÇADO]]+TB_INTEGRADA[[#This Row],[ORÇADO1]]+TB_INTEGRADA[[#This Row],[ORÇADO2]]+TB_INTEGRADA[[#This Row],[ORÇADO3]] -> 3166.8945 | AW11: =TB_INTEGRADA[[#This Row],[PLANEJ]]+TB_INTEGRADA[[#This Row],[PLANEJ1]]+TB_INTEGRADA[[#This Row],[PLANEJ2]]+TB_INTEGRADA[[#This Row],[PLANEJ3]] -> 1708 | AX11: =TB_INTEGRADA[[#This Row],[REALIZ]]+TB_INTEGRADA[[#This Row],[REALIZ1]]+TB_INTEGRADA[[#This Row],[REALIZ2]]+TB_INTEGRADA[[#This Row],[REALIZ3]] -> 3784 | AY11: =IFERROR(TB_INTEGRADA[[#This Row],[REALIZ4]]/TB_INTEGRADA[[#This Row],[ORÇADO4]],"") -> 1.1948614 | AZ11: =_xlfn.XLOOKUP(TB_INTEGRADA[[#This Row],[Nº SS]],'CONTROLE EC'!B:B,'CONTROLE EC'!W:W,"",0,1) -> 1342004 | BA11: =_xlfn.XLOOKUP(TB_INTEGRADA[[#This Row],[Nº SS]],'CONTROLE EC'!B:B,'CONTROLE EC'!X:X,"",0,1) -> 1342004 | BB11: =_xlfn.XLOOKUP(TB_INTEGRADA[[#This Row],[Nº SS]],'CONTROLE EC'!B:B,'CONTROLE EC'!Y:Y,"",0,1) -> 0
