Workbook
Name SegmentaçãodeDados_MOD___MOI: #N/A
Name SegmentaçãodeDados_SETOR: #N/A
Name SegmentaçãodeDados_SITUAÇÃO: #N/A
Name SegmentaçãodeDados_TOMADOR: #N/A
Name SegmentaçãodeDados_TOMADOR1: #N/A
Name SegmentaçãodeDados_TOMADOR2: #N/A

Sheet EFETIVO
B1: CONTROLE DE ATIVOS E INATIVOS: ES|MG | G1: PEDIDOS DE DESLIGAMENTO | H1: TAXA DE RENTENÇÃO | N1: ATUALIZAÇÃO: 09/03/2026
G2: 7 | H2: =1-G2/F4 -> 0.9125 | P2: MOI% | Q2: MOD%
F3: TOTAL EFETIVO | G3: MOI | H3: MOD | I3: ATIVOS | J3: INATIVOS | K3: FÉRIAS | L3: AFASTADOS | M3: TOTAL ADMISSÕES | N3: SALÁRIO MÉDIO ATUAL | P3: {=SUMPRODUCT(SUBTOTAL(9,OFFSET(A6,ROW(Tb_EFETIVO[CONTADOR])-ROW(A6),0)),(Tb_EFETIVO[TIPO]="MOI")+0,((Tb_EFETIVO[SITUAÇÃO]="ATIVO")+(Tb_EFETIVO[SITUAÇÃO]="AFASTADO")+(Tb_EFETIVO[SITUAÇÃO]="FÉRIAS")+(Tb_EFETIVO[SITUAÇÃO]="SERVIÇO MILITAR")+(Tb_EFETIVO[SITUAÇÃO]="DESMOBILIZAÇÃO"))+0)} -> 25 | Q3: {=SUMPRODUCT(SUBTOTAL(9,OFFSET(A6,ROW(A6:A108)-ROW(A6),0)),(I6:I108="MOD")+0,((N6:N108="ATIVO")+(N6:N108="AFASTADO")+(N6:N108="FÉRIAS")+(N6:N108="SERVIÇO MILITAR")+(N6:N108="DESMOBILIZAÇÃO"))+0)} -> 55
F4: =I4+K4+L4 -> 80 | G4: =IFERROR(P3&" ("&TEXT(ROUND(P4,2),"0%")&")","") -> 25 (31%) | H4: =IFERROR(Q3&" ("&TEXT(ROUND(Q4,2),"0%")&")","") -> 55 (69%) | I4: {=SUMPRODUCT(SUBTOTAL(9,OFFSET(A6,ROW(A6:A108)-ROW(A6),0)),(N6:N108="ATIVO")+0)} -> 80 | J4: {=SUMPRODUCT(SUBTOTAL(9,OFFSET(A6,ROW(A6:A108)-ROW(A6),0)),(N6:N108="INATIVO")+0)} -> 0 | K4: {=SUMPRODUCT(SUBTOTAL(9,OFFSET(A6,ROW(A6:A108)-ROW(A6),0)),(N6:N108="FÉRIAS")+0)} -> 0 | L4: {=SUMPRODUCT(SUBTOTAL(9,OFFSET(A6,ROW(A6:A108)-ROW(A6),0)),(N6:N108="AFASTADO")+0)} -> 0 | M4: =I4+J4 -> 80 | N4: {=SUMPRODUCT((SUBTOTAL(103,OFFSET(A6,ROW(Tb_EFETIVO[CONTADOR])-ROW(A6),0))*Tb_EFETIVO[SALÁRIO BASE])) / SUMPRODUCT(SUBTOTAL(103,OFFSET(A6,ROW(Tb_EFETIVO[CONTADOR])-ROW(A6),0)))} -> 4315.2851 | P4: =P3/F4 -> 0.3125 | Q4: =Q3/F4 -> 0.6875
A5: CONTADOR | B5: TOMADOR | C5: SINDICATO | D5: NOME COMPLETO | E5: FUNÇÃO | F5: SALÁRIO BASE | G5: SALÁRIO+PER | H5: ID PETROBRAS | I5: TIPO | J5: ADMISSÃO | K5: NASCIMENTO | L5: CPF | M5: DEMISSÃO | N5: SITUAÇÃO
A6: =IF(Tb_EFETIVO[[#This Row],[TOMADOR]]="",0,1) -> 1 | B6: EDIVIT | C6: =IF(B6="UTGC","SINTRACON",IF(B6="EDIVIT","SINTRACONST","")) -> SINTRACONST | D6: ADENILDO LARANJEIRA DOS SANTOS | E6: PEDREIRO | F6: =_xlfn.XLOOKUP(Tb_EFETIVO[[#This Row],[FUNÇÃO]],Tb_FUNÇÕES[RESUMO - FUNÇÕES],Tb_FUNÇÕES[SALÁRIO BASE],0,0,1) -> 3218.17 | G6: =IF(Tb_EFETIVO[[#This Row],[TOMADOR]]="UTGC",Tb_EFETIVO[[#This Row],[SALÁRIO BASE]]*1.3,Tb_EFETIVO[[#This Row],[SALÁRIO BASE]]) -> 3218.17 | H6: 72849101 | I6: MOD | J6: 45952 | K6: 24192 | L6: 86150634787 | M6: 46036 | N6: =IF(Tb_EFETIVO[[#This Row],[DEMISSÃO]]="","ATIVO","INATIVO") -> INATIVO
A7: =IF(Tb_EFETIVO[[#This Row],[TOMADOR]]="",0,1) -> 1 | B7: EDIVIT | C7: =IF(B7="UTGC","SINTRACON",IF(B7="EDIVIT","SINTRACONST","")) -> SINTRACONST | D7: ALEX GOMES DE OLIVEIRA | E7: ENCARREGADO DE CALDERARIA | F7: 6525.36 | G7: =IF(Tb_EFETIVO[[#This Row],[TOMADOR]]="UTGC",Tb_EFETIVO[[#This Row],[SALÁRIO BASE]]*1.3,Tb_EFETIVO[[#This Row],[SALÁRIO BASE]]) -> 6525.36 | H7: 72206513 | I7: MOI | J7: 46090 | K7: 34882 | L7: 04582075355 | N7: =IF(Tb_EFETIVO[[#This Row],[DEMISSÃO]]="","ATIVO","INATIVO") -> ATIVO
A8: =IF(Tb_EFETIVO[[#This Row],[TOMADOR]]="",0,1) -> 1 | B8: UTGC | C8: =IF(B8="UTGC","SINTRACON",IF(B8="EDIVIT","SINTRACONST","")) -> SINTRACON | D8: WESLEY FERNANDES LEOPOLDO | E8: PINTOR INDUSTRIAL ALPINISTA | F8: 3494.9 | G8: =IF(Tb_EFETIVO[[#This Row],[TOMADOR]]="UTGC",Tb_EFETIVO[[#This Row],[SALÁRIO BASE]]*1.3,Tb_EFETIVO[[#This Row],[SALÁRIO BASE]]) -> 4543.37 | H8: 71740945 | I8: MOD | J8: 46090 | K8: 35756 | L8: 17264171744 | N8: =IF(Tb_EFETIVO[[#This Row],[DEMISSÃO]]="","ATIVO","INATIVO") -> ATIVO
A9: =IF(Tb_EFETIVO[[#This Row],[TOMADOR]]="",0,1) -> 1 | B9: UTGC | C9: =IF(B9="UTGC","SINTRACON",IF(B9="EDIVIT","SINTRACONST","")) -> SINTRACON | D9: AGUINALDO KRULL CUSTÓDIO | E9: MECANICO MONTADOR | F9: =_xlfn.XLOOKUP(Tb_EFETIVO[[#This Row],[FUNÇÃO]],Tb_FUNÇÕES[RESUMO - FUNÇÕES],Tb_FUNÇÕES[SALÁRIO BASE],0,0,1) -> 3847.53 | G9: =IF(Tb_EFETIVO[[#This Row],[TOMADOR]]="UTGC",Tb_EFETIVO[[#This Row],[SALÁRIO BASE]]*1.3,Tb_EFETIVO[[#This Row],[SALÁRIO BASE]]) -> 5001.789 | H9: 42320998 | I9: MOD | J9: 45943 | K9: 30878 | L9: 02359862596 | M9: 46086 | N9: =IF(Tb_EFETIVO[[#This Row],[DEMISSÃO]]="","ATIVO","INATIVO") -> INATIVO
A10: =IF(Tb_EFETIVO[[#This Row],[TOMADOR]]="",0,1) -> 1 | B10: EDIVIT | C10: =IF(B10="UTGC","SINTRACON",IF(B10="EDIVIT","SINTRACONST","")) -> SINTRACONST | D10: AIRYS DAVIDSON PEREIRA DOS SANTOS | E10: TECNICO SEGURANÇA DO TRABALHO | F10: =_xlfn.XLOOKUP(Tb_EFETIVO[[#This Row],[FUNÇÃO]],Tb_FUNÇÕES[RESUMO - FUNÇÕES],Tb_FUNÇÕES[SALÁRIO BASE],0,0,1) -> 4425.3 | G10: =IF(Tb_EFETIVO[[#This Row],[TOMADOR]]="UTGC",Tb_EFETIVO[[#This Row],[SALÁRIO BASE]]*1.3,Tb_EFETIVO[[#This Row],[SALÁRIO BASE]]) -> 4425.3 | H10: 72810882 | I10: MOI | J10: 45918 | K10: 34921 | L10: 83134131234 | M10: 46013 | N10: =IF(Tb_EFETIVO[[#This Row],[DEMISSÃO]]="","ATIVO","INATIVO") -> INATIVO
A11: =IF(Tb_EFETIVO[[#This Row],[TOMADOR]]="",0,1) -> 1 | B11: EDIVIT | C11: =IF(B11="UTGC","SINTRACON",IF(B11="EDIVIT","SINTRACONST","")) -> SINTRACONST | D11: ALBERTO COSTA DE JESUS | E11: PEDREIRO | F11: =_xlfn.XLOOKUP(Tb_EFETIVO[[#This Row],[FUNÇÃO]],Tb_FUNÇÕES[RESUMO - FUNÇÕES],Tb_FUNÇÕES[SALÁRIO BASE],0,0,1) -> 3218.17 | G11: =IF(Tb_EFETIVO[[#This Row],[TOMADOR]]="UTGC",Tb_EFETIVO[[#This Row],[SALÁRIO BASE]]*1.3,Tb_EFETIVO[[#This Row],[SALÁRIO BASE]]) -> 3218.17 | H11: 43982181 | I11: MOD | J11: 45952 | K11: 23522 | L11: 31332650597 | M11: 46036 | N11: =IF(Tb_EFETIVO[[#This Row],[DEMISSÃO]]="","ATIVO","INATIVO") -> INATIVO
A12: =IF(Tb_EFETIVO[[#This Row],[TOMADOR]]="",0,1) -> 1 | B12: UTGC | C12: =IF(B12="UTGC","SINTRACON",IF(B12="EDIVIT","SINTRACONST","")) -> SINTRACON | D12: ALISON PEREIRA BARBOSA | E12: CALDEIREIRO | F12: =_xlfn.XLOOKUP(Tb_EFETIVO[[#This Row],[FUNÇÃO]],Tb_FUNÇÕES[RESUMO - FUNÇÕES],Tb_FUNÇÕES[SALÁRIO BASE],0,0,1) -> 4402.45 | G12: =IF(Tb_EFETIVO[[#This Row],[TOMADOR]]="UTGC",Tb_EFETIVO[[#This Row],[SALÁRIO BASE]]*1.3,Tb_EFETIVO[[#This Row],[SALÁRIO BASE]]) -> 5723.185 | H12: 41917596 | I12: MOD | J12: 45967 | K12: 32443 | L12: 12342344759 | N12: =IF(Tb_EFETIVO[[#This Row],[DEMISSÃO]]="","ATIVO","INATIVO") -> ATIVO
A13: =IF(Tb_EFETIVO[[#This Row],[TOMADOR]]="",0,1) -> 1 | B13: UTGC | C13: =IF(B13="UTGC","SINTRACON",IF(B13="EDIVIT","SINTRACONST","")) -> SINTRACON | D13: ANGELO GABRIEL DE ALMEIDA SILVA | E13: MECANICO MONTADOR | F13: 3847.53 | G13: =IF(Tb_EFETIVO[[#This Row],[TOMADOR]]="UTGC",Tb_EFETIVO[[#This Row],[SALÁRIO BASE]]*1.3,Tb_EFETIVO[[#This Row],[SALÁRIO BASE]]) -> 5001.789 | H13: 71642061 | I13: MOD | J13: 46062 | K13: 36284 | L13: 18033541784 | N13: =IF(Tb_EFETIVO[[#This Row],[DEMISSÃO]]="","ATIVO","INATIVO") -> ATIVO
A14: =IF(Tb_EFETIVO[[#This Row],[TOMADOR]]="",0,1) -> 1 | B14: UTGC | C14: =IF(B14="UTGC","SINTRACON",IF(B14="EDIVIT","SINTRACONST","")) -> SINTRACON | D14: ANTONIO DOMINGOS DOS SANTOS JUNIOR | E14: PINTOR INDUSTRIAL ALPINISTA | F14: =_xlfn.XLOOKUP(Tb_EFETIVO[[#This Row],[FUNÇÃO]],Tb_FUNÇÕES[RESUMO - FUNÇÕES],Tb_FUNÇÕES[SALÁRIO BASE],0,0,1) -> 3494.9 | G14: =IF(Tb_EFETIVO[[#This Row],[TOMADOR]]="UTGC",Tb_EFETIVO[[#This Row],[SALÁRIO BASE]]*1.3,Tb_EFETIVO[[#This Row],[SALÁRIO BASE]]) -> 4543.37 | H14: 72401331 | I14: MOD | J14: 45950 | K14: 37464 | L14: 15237930743 | N14: =IF(Tb_EFETIVO[[#This Row],[DEMISSÃO]]="","ATIVO","INATIVO") -> ATIVO
A15: =IF(Tb_EFETIVO[[#This Row],[TOMADOR]]="",0,1) -> 1 | B15: EDIVIT | C15: =IF(B15="UTGC","SINTRACON",IF(B15="EDIVIT","SINTRACONST","")) -> SINTRACONST | D15: BRAYON LOPES DA SILVA | E15: TECNICO SEGURANÇA DO TRABALHO | F15: =_xlfn.XLOOKUP(Tb_EFETIVO[[#This Row],[FUNÇÃO]],Tb_FUNÇÕES[RESUMO - FUNÇÕES],Tb_FUNÇÕES[SALÁRIO BASE],0,0,1) -> 4425.3 | G15: =IF(Tb_EFETIVO[[#This Row],[TOMADOR]]="UTGC",Tb_EFETIVO[[#This Row],[SALÁRIO BASE]]*1.3,Tb_EFETIVO[[#This Row],[SALÁRIO BASE]]) -> 4425.3 | H15: 72375610 | I15: MOI | J15: 45922 | K15: 32438 | L15: 12302409779 | N15: =IF(Tb_EFETIVO[[#This Row],[DEMISSÃO]]="","ATIVO","INATIVO") -> ATIVO
A16: =IF(Tb_EFETIVO[[#This Row],[TOMADOR]]="",0,1) -> 1 | B16: UTGC | C16: =IF(B16="UTGC","SINTRACON",IF(B16="EDIVIT","SINTRACONST","")) -> SINTRACON | D16: CARLOS DA CONCEIÇÃO DE SOUZA | E16: AJUDANTE DE CIVIL | F16: =_xlfn.XLOOKUP(Tb_EFETIVO[[#This Row],[FUNÇÃO]],Tb_FUNÇÕES[RESUMO - FUNÇÕES],Tb_FUNÇÕES[SALÁRIO BASE],0,0,1) -> 1726.63 | G16: =IF(Tb_EFETIVO[[#This Row],[TOMADOR]]="UTGC",Tb_EFETIVO[[#This Row],[SALÁRIO BASE]]*1.3,Tb_EFETIVO[[#This Row],[SALÁRIO BASE]]) -> 2244.619 | H16: 72070771 | I16: MOD | J16: 45943 | K16: 38415 | L16: 20295327707 | N16: =IF(Tb_EFETIVO[[#This Row],[DEMISSÃO]]="","ATIVO","INATIVO") -> ATIVO
A17: =IF(Tb_EFETIVO[[#This Row],[TOMADOR]]="",0,1) -> 1 | B17: EDIVIT | C17: =IF(B17="UTGC","SINTRACON",IF(B17="EDIVIT","SINTRACONST","")) -> SINTRACONST | D17: CARLOS EDUARDO BRAGA DA COSTA | E17: ELETRICISTA | F17: =_xlfn.XLOOKUP(Tb_EFETIVO[[#This Row],[FUNÇÃO]],Tb_FUNÇÕES[RESUMO - FUNÇÕES],Tb_FUNÇÕES[SALÁRIO BASE],0,0,1) -> 3328.48 | G17: =IF(Tb_EFETIVO[[#This Row],[TOMADOR]]="UTGC",Tb_EFETIVO[[#This Row],[SALÁRIO BASE]]*1.3,Tb_EFETIVO[[#This Row],[SALÁRIO BASE]]) -> 3328.48 | H17: 72899847 | I17: MOD | J17: 45992 | K17: 37060 | L17: 18510528799 | N17: =IF(Tb_EFETIVO[[#This Row],[DEMISSÃO]]="","ATIVO","INATIVO") -> ATIVO
A18: =IF(Tb_EFETIVO[[#This Row],[TOMADOR]]="",0,1) -> 1 | B18: EDIVIT | C18: =IF(B18="UTGC","SINTRACON",IF(B18="EDIVIT","SINTRACONST","")) -> SINTRACONST | D18: CARLOS RODRIGO ALMEIDA | E18: CALDEIREIRO | F18: =_xlfn.XLOOKUP(Tb_EFETIVO[[#This Row],[FUNÇÃO]],Tb_FUNÇÕES[RESUMO - FUNÇÕES],Tb_FUNÇÕES[SALÁRIO BASE],0,0,1) -> 4402.45 | G18: =IF(Tb_EFETIVO[[#This Row],[TOMADOR]]="UTGC",Tb_EFETIVO[[#This Row],[SALÁRIO BASE]]*1.3,Tb_EFETIVO[[#This Row],[SALÁRIO BASE]]) -> 4402.45 | H18: 72849094 | I18: MOD | J18: 45952 | K18: 31136 | L18: 9731561714 | M18: 45966 | N18: =IF(Tb_EFETIVO[[#This Row],[DEMISSÃO]]="","ATIVO","INATIVO") -> INATIVO
A19: =IF(Tb_EFETIVO[[#This Row],[TOMADOR]]="",0,1) -> 1 | B19: EDIVIT | C19: =IF(B19="UTGC","SINTRACON",IF(B19="EDIVIT","SINTRACONST","")) -> SINTRACONST | D19: CRISPIM OLIVEIRA DOS SANTOS | E19: AJUDANTE DE OBRAS | F19: =_xlfn.XLOOKUP(Tb_EFETIVO[[#This Row],[FUNÇÃO]],Tb_FUNÇÕES[RESUMO - FUNÇÕES],Tb_FUNÇÕES[SALÁRIO BASE],0,0,1) -> 1726.63 | G19: =IF(Tb_EFETIVO[[#This Row],[TOMADOR]]="UTGC",Tb_EFETIVO[[#This Row],[SALÁRIO BASE]]*1.3,Tb_EFETIVO[[#This Row],[SALÁRIO BASE]]) -> 1726.63 | H19: 72899779 | I19: MOD | J19: 45992 | K19: 29543 | L19: 02227458518 | M19: 46083 | N19: =IF(Tb_EFETIVO[[#This Row],[DEMISSÃO]]="","ATIVO","INATIVO") -> INATIVO
A20: =IF(Tb_EFETIVO[[#This Row],[TOMADOR]]="",0,1) -> 1 | B20: UTGC | C20: =IF(B20="UTGC","SINTRACON",IF(B20="EDIVIT","SINTRACONST","")) -> SINTRACON | D20: DANIEL DA CONCEIÇÃO FLORO JUNIOR | E20: AJUDANTE DE OBRAS | F20: =_xlfn.XLOOKUP(Tb_EFETIVO[[#This Row],[FUNÇÃO]],Tb_FUNÇÕES[RESUMO - FUNÇÕES],Tb_FUNÇÕES[SALÁRIO BASE],0,0,1) -> 1726.63 | G20: =IF(Tb_EFETIVO[[#This Row],[TOMADOR]]="UTGC",Tb_EFETIVO[[#This Row],[SALÁRIO BASE]]*1.3,Tb_EFETIVO[[#This Row],[SALÁRIO BASE]]) -> 2244.619 | H20: 72253077 | I20: MOD | J20: 45967 | K20: 36555 | L20: 14267811725 | M20: 46036 | N20: =IF(Tb_EFETIVO[[#This Row],[DEMISSÃO]]="","ATIVO","INATIVO") -> INATIVO
A21: =IF(Tb_EFETIVO[[#This Row],[TOMADOR]]="",0,1) -> 1 | B21: EDIVIT | C21: =IF(B21="UTGC","SINTRACON",IF(B21="EDIVIT","SINTRACONST","")) -> SINTRACONST | D21: DANIEL NUNES MOTA | E21: ALMOXARIFE DE OBRAS | F21: =_xlfn.XLOOKUP(Tb_EFETIVO[[#This Row],[FUNÇÃO]],Tb_FUNÇÕES[RESUMO - FUNÇÕES],Tb_FUNÇÕES[SALÁRIO BASE],0,0,1) -> 3000 | G21: =IF(Tb_EFETIVO[[#This Row],[TOMADOR]]="UTGC",Tb_EFETIVO[[#This Row],[SALÁRIO BASE]]*1.3,Tb_EFETIVO[[#This Row],[SALÁRIO BASE]]) -> 3000 | H21: 72533874 | I21: MOI | J21: 45917 | K21: 36840 | L21: 18649093744 | N21: =IF(Tb_EFETIVO[[#This Row],[DEMISSÃO]]="","ATIVO","INATIVO") -> ATIVO
A22: =IF(Tb_EFETIVO[[#This Row],[TOMADOR]]="",0,1) -> 1 | B22: UTGC | C22: =IF(B22="UTGC","SINTRACON",IF(B22="EDIVIT","SINTRACONST","")) -> SINTRACON | D22: DEYVID ALAN OLIVEIRA MUNIZ | E22: PEDREIRO | F22: =_xlfn.XLOOKUP(Tb_EFETIVO[[#This Row],[FUNÇÃO]],Tb_FUNÇÕES[RESUMO - FUNÇÕES],Tb_FUNÇÕES[SALÁRIO BASE],0,0,1) -> 3218.17 | G22: =IF(Tb_EFETIVO[[#This Row],[TOMADOR]]="UTGC",Tb_EFETIVO[[#This Row],[SALÁRIO BASE]]*1.3,Tb_EFETIVO[[#This Row],[SALÁRIO BASE]]) -> 4183.621 | H22: 71787090 | I22: MOD | J22: 45943 | K22: 35504 | L22: 15262186742 | N22: =IF(Tb_EFETIVO[[#This Row],[DEMISSÃO]]="","ATIVO","INATIVO") -> ATIVO
A23: =IF(Tb_EFETIVO[[#This Row],[TOMADOR]]="",0,1) -> 1 | B23: UTGC | C23: =IF(B23="UTGC","SINTRACON",IF(B23="EDIVIT","SINTRACONST","")) -> SINTRACON | D23: DIEKSON VALERIANO DOS REIS | E23: MECANICO MONTADOR | F23: =_xlfn.XLOOKUP(Tb_EFETIVO[[#This Row],[FUNÇÃO]],Tb_FUNÇÕES[RESUMO - FUNÇÕES],Tb_FUNÇÕES[SALÁRIO BASE],0,0,1) -> 3847.53 | G23: =IF(Tb_EFETIVO[[#This Row],[TOMADOR]]="UTGC",Tb_EFETIVO[[#This Row],[SALÁRIO BASE]]*1.3,Tb_EFETIVO[[#This Row],[SALÁRIO BASE]]) -> 5001.789 | H23: 43788046 | I23: MOD | J23: 45931 | K23: 32563 | L23: 12530818754 | N23: =IF(Tb_EFETIVO[[#This Row],[DEMISSÃO]]="","ATIVO","INATIVO") -> ATIVO
A24: =IF(Tb_EFETIVO[[#This Row],[TOMADOR]]="",0,1) -> 1 | B24: EDIVIT | C24: =IF(B24="UTGC","SINTRACON",IF(B24="EDIVIT","SINTRACONST","")) -> SINTRACONST | D24: DIRCEU CARAPINA | E24: ENCARREGADO DE CALDERARIA | F24: =_xlfn.XLOOKUP(Tb_EFETIVO[[#This Row],[FUNÇÃO]],Tb_FUNÇÕES[RESUMO - FUNÇÕES],Tb_FUNÇÕES[SALÁRIO BASE],0,0,1) -> 6525.36 | G24: =IF(Tb_EFETIVO[[#This Row],[TOMADOR]]="UTGC",Tb_EFETIVO[[#This Row],[SALÁRIO BASE]]*1.3,Tb_EFETIVO[[#This Row],[SALÁRIO BASE]]) -> 6525.36 | H24: 72825975 | I24: MOI | J24: 45922 | K24: 24456 | L24: 00294927778 | M24: 46093 | N24: =IF(Tb_EFETIVO[[#This Row],[DEMISSÃO]]="","ATIVO","INATIVO") -> INATIVO
A25: =IF(Tb_EFETIVO[[#This Row],[TOMADOR]]="",0,1) -> 1 | B25: UTGC | C25: =IF(B25="UTGC","SINTRACON",IF(B25="EDIVIT","SINTRACONST","")) -> SINTRACON | D25: DONIZETE DA CONCEIÇÃO SILVA | E25: AJUDANTE DE CIVIL | F25: =_xlfn.XLOOKUP(Tb_EFETIVO[[#This Row],[FUNÇÃO]],Tb_FUNÇÕES[RESUMO - FUNÇÕES],Tb_FUNÇÕES[SALÁRIO BASE],0,0,1) -> 1726.63 | G25: =IF(Tb_EFETIVO[[#This Row],[TOMADOR]]="UTGC",Tb_EFETIVO[[#This Row],[SALÁRIO BASE]]*1.3,Tb_EFETIVO[[#This Row],[SALÁRIO BASE]]) -> 2244.619 | H25: 72253077 | I25: MOD | J25: 45967 | K25: 36693 | L25: 19153278739 | N25: =IF(Tb_EFETIVO[[#This Row],[DEMISSÃO]]="","ATIVO","INATIVO") -> ATIVO
A26: =IF(Tb_EFETIVO[[#This Row],[TOMADOR]]="",0,1) -> 1 | B26: UTGC | C26: =IF(B26="UTGC","SINTRACON",IF(B26="EDIVIT","SINTRACONST","")) -> SINTRACON | D26: DOUGLIAN MORAES TIMBUIBA | E26: PINTOR INDUSTRIAL ALPINISTA | F26: =_xlfn.XLOOKUP(Tb_EFETIVO[[#This Row],[FUNÇÃO]],Tb_FUNÇÕES[RESUMO - FUNÇÕES],Tb_FUNÇÕES[SALÁRIO BASE],0,0,1) -> 3494.9 | G26: =IF(Tb_EFETIVO[[#This Row],[TOMADOR]]="UTGC",Tb_EFETIVO[[#This Row],[SALÁRIO BASE]]*1.3,Tb_EFETIVO[[#This Row],[SALÁRIO BASE]]) -> 4543.37 | H26: 71742188 | I26: MOD | J26: 45978 | K26: 35037 | L26: 15656507785 | N26: =IF(Tb_EFETIVO[[#This Row],[DEMISSÃO]]="","ATIVO","INATIVO") -> ATIVO
A27: =IF(Tb_EFETIVO[[#This Row],[TOMADOR]]="",0,1) -> 1 | B27: EDIVIT | C27: =IF(B27="UTGC","SINTRACON",IF(B27="EDIVIT","SINTRACONST","")) -> SINTRACONST | D27: EDCASSIA RIBEIRO GOMES DUTRA | E27: ASSISTENTE ADMINISTRATIVO | F27: =_xlfn.XLOOKUP(Tb_EFETIVO[[#This Row],[FUNÇÃO]],Tb_FUNÇÕES[RESUMO - FUNÇÕES],Tb_FUNÇÕES[SALÁRIO BASE],0,0,1) -> 3800 | G27: =IF(Tb_EFETIVO[[#This Row],[TOMADOR]]="UTGC",Tb_EFETIVO[[#This Row],[SALÁRIO BASE]]*1.3,Tb_EFETIVO[[#This Row],[SALÁRIO BASE]]) -> 3800 | H27: 72176910 | I27: MOI | J27: 45910 | K27: 35831 | L27: 16933421708 | N27: =IF(Tb_EFETIVO[[#This Row],[DEMISSÃO]]="","ATIVO","INATIVO") -> ATIVO
A28: =IF(Tb_EFETIVO[[#This Row],[TOMADOR]]="",0,1) -> 1 | B28: UTGC | C28: =IF(B28="UTGC","SINTRACON",IF(B28="EDIVIT","SINTRACONST","")) -> SINTRACON | D28: EDINALDO SILVA DOS ANJOS JUNIOR | E28: AJUDANTE DE OBRAS | F28: =_xlfn.XLOOKUP(Tb_EFETIVO[[#This Row],[FUNÇÃO]],Tb_FUNÇÕES[RESUMO - FUNÇÕES],Tb_FUNÇÕES[SALÁRIO BASE],0,0,1) -> 1726.63 | G28: =IF(Tb_EFETIVO[[#This Row],[TOMADOR]]="UTGC",Tb_EFETIVO[[#This Row],[SALÁRIO BASE]]*1.3,Tb_EFETIVO[[#This Row],[SALÁRIO BASE]]) -> 2244.619 | H28: 72397720 | I28: MOD | J28: 45967 | K28: 35404 | L28: 14883940756 | M28: 46003 | N28: =IF(Tb_EFETIVO[[#This Row],[DEMISSÃO]]="","ATIVO","INATIVO") -> INATIVO
A29: =IF(Tb_EFETIVO[[#This Row],[TOMADOR]]="",0,1) -> 1 | B29: UTGC | C29: =IF(B29="UTGC","SINTRACON",IF(B29="EDIVIT","SINTRACONST","")) -> SINTRACON | D29: EDNALDO SANTOS FLORES | E29: PEDREIRO | F29: 3218.17 | G29: =IF(Tb_EFETIVO[[#This Row],[TOMADOR]]="UTGC",Tb_EFETIVO[[#This Row],[SALÁRIO BASE]]*1.3,Tb_EFETIVO[[#This Row],[SALÁRIO BASE]]) -> 4183.621 | H29: 43367701 | I29: MOD | J29: 46062 | K29: 31245 | L29: 02205199510 | N29: =IF(Tb_EFETIVO[[#This Row],[DEMISSÃO]]="","ATIVO","INATIVO") -> ATIVO
A30: =IF(Tb_EFETIVO[[#This Row],[TOMADOR]]="",0,1) -> 1 | B30: UTGC | C30: =IF(B30="UTGC","SINTRACON",IF(B30="EDIVIT","SINTRACONST","")) -> SINTRACON | D30: EDUARDO ANDRADE CECILIO | E30: AJUDANTE DE OBRAS | F30: =_xlfn.XLOOKUP(Tb_EFETIVO[[#This Row],[FUNÇÃO]],Tb_FUNÇÕES[RESUMO - FUNÇÕES],Tb_FUNÇÕES[SALÁRIO BASE],0,0,1) -> 1726.63 | G30: =IF(Tb_EFETIVO[[#This Row],[TOMADOR]]="UTGC",Tb_EFETIVO[[#This Row],[SALÁRIO BASE]]*1.3,Tb_EFETIVO[[#This Row],[SALÁRIO BASE]]) -> 2244.619 | H30: 72870958 | I30: MOD | J30: 45967 | K30: 38995 | L30: 21728943701 | M30: 46029 | N30: =IF(Tb_EFETIVO[[#This Row],[DEMISSÃO]]="","ATIVO","INATIVO") -> INATIVO
A31: =IF(Tb_EFETIVO[[#This Row],[TOMADOR]]="",0,1) -> 1 | B31: UTGC | C31: =IF(B31="UTGC","SINTRACON",IF(B31="EDIVIT","SINTRACONST","")) -> SINTRACON | D31: EDUARDO INACIA COSTA | E31: CALDEIREIRO | F31: 4402.45 | G31: =IF(Tb_EFETIVO[[#This Row],[TOMADOR]]="UTGC",Tb_EFETIVO[[#This Row],[SALÁRIO BASE]]*1.3,Tb_EFETIVO[[#This Row],[SALÁRIO BASE]]) -> 5723.185 | H31: 40480704 | I31: MOD | J31: 46062 | K31: 29997 | L31: 00354234552 | N31: =IF(Tb_EFETIVO[[#This Row],[DEMISSÃO]]="","ATIVO","INATIVO") -> ATIVO
A32: =IF(Tb_EFETIVO[[#This Row],[TOMADOR]]="",0,1) -> 1 | B32: EDIVIT | C32: =IF(B32="UTGC","SINTRACON",IF(B32="EDIVIT","SINTRACONST","")) -> SINTRACONST | D32: ELISEU GOMES | E32: TECNICO DE PLANEJAMENTO | F32: =_xlfn.XLOOKUP(Tb_EFETIVO[[#This Row],[FUNÇÃO]],Tb_FUNÇÕES[RESUMO - FUNÇÕES],Tb_FUNÇÕES[SALÁRIO BASE],0,0,1) -> 4425.3 | G32: =IF(Tb_EFETIVO[[#This Row],[TOMADOR]]="UTGC",Tb_EFETIVO[[#This Row],[SALÁRIO BASE]]*1.3,Tb_EFETIVO[[#This Row],[SALÁRIO BASE]]) -> 4425.3 | H32: 49732836 | I32: MOI | J32: 45919 | K32: 21969 | L32: 60691271704 | N32: =IF(Tb_EFETIVO[[#This Row],[DEMISSÃO]]="","ATIVO","INATIVO") -> ATIVO
A33: =IF(Tb_EFETIVO[[#This Row],[TOMADOR]]="",0,1) -> 1 | B33: UTGC | C33: =IF(B33="UTGC","SINTRACON",IF(B33="EDIVIT","SINTRACONST","")) -> SINTRACON | D33: ELIVALDO DE OLIVEIRA | E33: PEDREIRO | F33: =_xlfn.XLOOKUP(Tb_EFETIVO[[#This Row],[FUNÇÃO]],Tb_FUNÇÕES[RESUMO - FUNÇÕES],Tb_FUNÇÕES[SALÁRIO BASE],0,0,1) -> 3218.17 | G33: =IF(Tb_EFETIVO[[#This Row],[TOMADOR]]="UTGC",Tb_EFETIVO[[#This Row],[SALÁRIO BASE]]*1.3,Tb_EFETIVO[[#This Row],[SALÁRIO BASE]]) -> 4183.621 | H33: 42986890 | I33: MOD | J33: 45967 | K33: 24191 | L33: 95248749700 | N33: =IF(Tb_EFETIVO[[#This Row],[DEMISSÃO]]="","ATIVO","INATIVO") -> ATIVO
A34: =IF(Tb_EFETIVO[[#This Row],[TOMADOR]]="",0,1) -> 1 | B34: UTGC | C34: =IF(B34="UTGC","SINTRACON",IF(B34="EDIVIT","SINTRACONST","")) -> SINTRACON | D34: ELTON LEITE DE SOUZA | E34: ELETRICISTA | F34: =_xlfn.XLOOKUP(Tb_EFETIVO[[#This Row],[FUNÇÃO]],Tb_FUNÇÕES[RESUMO - FUNÇÕES],Tb_FUNÇÕES[SALÁRIO BASE],0,0,1) -> 3328.48 | G34: =IF(Tb_EFETIVO[[#This Row],[TOMADOR]]="UTGC",Tb_EFETIVO[[#This Row],[SALÁRIO BASE]]*1.3,Tb_EFETIVO[[#This Row],[SALÁRIO BASE]]) -> 4327.024 | H34: 42060674 | I34: MOD | J34: 45992 | K34: 30443 | L34: 09572615785 | N34: =IF(Tb_EFETIVO[[#This Row],[DEMISSÃO]]="","ATIVO","INATIVO") -> ATIVO
A35: =IF(Tb_EFETIVO[[#This Row],[TOMADOR]]="",0,1) -> 1 | B35: UTGC | C35: =IF(B35="UTGC","SINTRACON",IF(B35="EDIVIT","SINTRACONST","")) -> SINTRACON | D35: ENEAS SANTANA DA SILVA | E35: PEDREIRO | F35: =_xlfn.XLOOKUP(Tb_EFETIVO[[#This Row],[FUNÇÃO]],Tb_FUNÇÕES[RESUMO - FUNÇÕES],Tb_FUNÇÕES[SALÁRIO BASE],0,0,1) -> 3218.17 | G35: =IF(Tb_EFETIVO[[#This Row],[TOMADOR]]="UTGC",Tb_EFETIVO[[#This Row],[SALÁRIO BASE]]*1.3,Tb_EFETIVO[[#This Row],[SALÁRIO BASE]]) -> 4183.621 | H35: 48275334 | I35: MOD | J35: 45967 | K35: 28283 | L35: 00156073560 | N35: =IF(Tb_EFETIVO[[#This Row],[DEMISSÃO]]="","ATIVO","INATIVO") -> ATIVO
A36: =IF(Tb_EFETIVO[[#This Row],[TOMADOR]]="",0,1) -> 1 | B36: UTGC | C36: =IF(B36="UTGC","SINTRACON",IF(B36="EDIVIT","SINTRACONST","")) -> SINTRACON | D36: ESTHEVAN RIBEIRO FRANCA | E36: MECANICO MONTADOR | F36: =_xlfn.XLOOKUP(Tb_EFETIVO[[#This Row],[FUNÇÃO]],Tb_FUNÇÕES[RESUMO - FUNÇÕES],Tb_FUNÇÕES[SALÁRIO BASE],0,0,1) -> 3847.53 | G36: =IF(Tb_EFETIVO[[#This Row],[TOMADOR]]="UTGC",Tb_EFETIVO[[#This Row],[SALÁRIO BASE]]*1.3,Tb_EFETIVO[[#This Row],[SALÁRIO BASE]]) -> 5001.789 | H36: 70724007 | I36: MOD | J36: 45931 | K36: 34446 | L36: 14122874726 | N36: =IF(Tb_EFETIVO[[#This Row],[DEMISSÃO]]="","ATIVO","INATIVO") -> ATIVO
A37: =IF(Tb_EFETIVO[[#This Row],[TOMADOR]]="",0,1) -> 1 | B37: EDIVIT | C37: =IF(B37="UTGC","SINTRACON",IF(B37="EDIVIT","SINTRACONST","")) -> SINTRACONST | D37: FELIPE KAYAN FAUSTINO FERREIRA | E37: AJUDANTE DE OBRAS | F37: =_xlfn.XLOOKUP(Tb_EFETIVO[[#This Row],[FUNÇÃO]],Tb_FUNÇÕES[RESUMO - FUNÇÕES],Tb_FUNÇÕES[SALÁRIO BASE],0,0,1) -> 1726.63 | G37: =IF(Tb_EFETIVO[[#This Row],[TOMADOR]]="UTGC",Tb_EFETIVO[[#This Row],[SALÁRIO BASE]]*1.3,Tb_EFETIVO[[#This Row],[SALÁRIO BASE]]) -> 1726.63 | H37: 72533677 | I37: MOD | J37: 45952 | K37: 35709 | L37: 17617319711 | N37: =IF(Tb_EFETIVO[[#This Row],[DEMISSÃO]]="","ATIVO","INATIVO") -> ATIVO
A38: =IF(Tb_EFETIVO[[#This Row],[TOMADOR]]="",0,1) -> 1 | B38: EDIVIT | C38: =IF(B38="UTGC","SINTRACON",IF(B38="EDIVIT","SINTRACONST","")) -> SINTRACONST | D38: FELIPE SOARES CAMPOS | E38: ELETRICISTA | F38: =_xlfn.XLOOKUP(Tb_EFETIVO[[#This Row],[FUNÇÃO]],Tb_FUNÇÕES[RESUMO - FUNÇÕES],Tb_FUNÇÕES[SALÁRIO BASE],0,0,1) -> 3328.48 | G38: =IF(Tb_EFETIVO[[#This Row],[TOMADOR]]="UTGC",Tb_EFETIVO[[#This Row],[SALÁRIO BASE]]*1.3,Tb_EFETIVO[[#This Row],[SALÁRIO BASE]]) -> 3328.48 | H38: 72567750 | I38: MOD | J38: 45938 | K38: 35231 | L38: 15462152710 | N38: =IF(Tb_EFETIVO[[#This Row],[DEMISSÃO]]="","ATIVO","INATIVO") -> ATIVO
A39: =IF(Tb_EFETIVO[[#This Row],[TOMADOR]]="",0,1) -> 1 | B39: EDIVIT | C39: =IF(B39="UTGC","SINTRACON",IF(B39="EDIVIT","SINTRACONST","")) -> SINTRACONST | D39: GABRIEL DAS NEVES GOMES | E39: AJUDANTE DE OBRAS | F39: =_xlfn.XLOOKUP(Tb_EFETIVO[[#This Row],[FUNÇÃO]],Tb_FUNÇÕES[RESUMO - FUNÇÕES],Tb_FUNÇÕES[SALÁRIO BASE],0,0,1) -> 1726.63 | G39: =IF(Tb_EFETIVO[[#This Row],[TOMADOR]]="UTGC",Tb_EFETIVO[[#This Row],[SALÁRIO BASE]]*1.3,Tb_EFETIVO[[#This Row],[SALÁRIO BASE]]) -> 1726.63 | H39: 72899903 | I39: MOD | J39: 45992 | K39: 37785 | L39: 19424149786 | N39: =IF(Tb_EFETIVO[[#This Row],[DEMISSÃO]]="","ATIVO","INATIVO") -> ATIVO
A40: =IF(Tb_EFETIVO[[#This Row],[TOMADOR]]="",0,1) -> 1 | B40: UTGC | C40: =IF(B40="UTGC","SINTRACON",IF(B40="EDIVIT","SINTRACONST","")) -> SINTRACON | D40: GEILSON CARLOS | E40: AJUDANTE DE CALDEIRARIA | F40: =_xlfn.XLOOKUP(Tb_EFETIVO[[#This Row],[FUNÇÃO]],Tb_FUNÇÕES[RESUMO - FUNÇÕES],Tb_FUNÇÕES[SALÁRIO BASE],0,0,1) -> 1726.63 | G40: =IF(Tb_EFETIVO[[#This Row],[TOMADOR]]="UTGC",Tb_EFETIVO[[#This Row],[SALÁRIO BASE]]*1.3,Tb_EFETIVO[[#This Row],[SALÁRIO BASE]]) -> 2244.619 | H40: 40425499 | I40: MOD | J40: 45943 | K40: 27674 | L40: 08257322717 | N40: =IF(Tb_EFETIVO[[#This Row],[DEMISSÃO]]="","ATIVO","INATIVO") -> ATIVO
...

Sheet CUSTO ESTIMADO
A1: =SUBTOTAL(103,tb_Custo[TOMADOR]) -> 47 | G1: =SUBTOTAL(109,tb_Custo[SALÁRIO BASE]) -> 161308.3 | H1: =SUBTOTAL(109,tb_Custo[SALÁRIO+PER]) -> 209700.79 | I1: =SUBTOTAL(109,tb_Custo[ALIMENTAÇÃO]) -> 49243.38 | J1: =SUBTOTAL(109,tb_Custo[TRANSPORTE]) -> 31500 | K1: =SUBTOTAL(109,tb_Custo[PLANOS SAÚDE+ODONTO]) -> 21402 | L1: =SUBTOTAL(109,tb_Custo[SEGURO DE VIDA]) -> 509.4 | M1: =SUBTOTAL(109,tb_Custo[AJUDA DE CUSTO]) -> 0 | N1: =SUBTOTAL(109,tb_Custo[ENCARGOS TRABALHISTAS]) -> 167760.63 | O1: =SUBTOTAL(109,tb_Custo[TOTAL INDIVIDUAL]) -> 480116.2 | P1: 220
A2: TOMADOR | B2: NOME COMPLETO | C2: FUNÇÃO | D2: SITUAÇÃO | E2: TIPO | F2: ADMISSÃO | G2: SALÁRIO BASE | H2: SALÁRIO+PER | I2: ALIMENTAÇÃO | J2: TRANSPORTE | K2: PLANOS SAÚDE+ODONTO | L2: SEGURO DE VIDA | M2: AJUDA DE CUSTO | N2: ENCARGOS TRABALHISTAS | O2: TOTAL INDIVIDUAL | P2: CUSTO HH
A3: UTGC | B3: KERGINALDO VICTOR DA SILVA FILHO | C3: COORDENADOR DE PLANEJAMENTO | D3: =_xlfn.XLOOKUP(tb_Custo[[#This Row],[NOME COMPLETO]],Tb_EFETIVO[NOME COMPLETO],Tb_EFETIVO[SITUAÇÃO],"",0,1) -> ATIVO | E3: MOI | F3: 45910 | G3: =_xlfn.XLOOKUP(C3,Tb_FUNÇÕES[RESUMO - FUNÇÕES],Tb_FUNÇÕES[SALÁRIO BASE],"",0,1) -> 14000 | H3: =IF(tb_Custo[[#This Row],[TOMADOR]]="UTGC",tb_Custo[[#This Row],[SALÁRIO BASE]]*1.3,tb_Custo[[#This Row],[SALÁRIO BASE]]) -> 18200 | I3: 1100 | J3: 0 | K3: 246 | L3: 11.32 | M3: 5000 | N3: =tb_Custo[[#This Row],[SALÁRIO+PER]]*0.8 -> 14560 | O3: =SUM(tb_Custo[[#This Row],[SALÁRIO+PER]:[ENCARGOS TRABALHISTAS]]) -> 39117.32 | P3: =tb_Custo[[#This Row],[TOTAL INDIVIDUAL]]/$P$1 -> 177.806
A4: UTGC | B4: RODRIGO FERREIRA DOS SANTOS | C4: ENGENHEIRO ORÇAMENTISTA | D4: =_xlfn.XLOOKUP(tb_Custo[[#This Row],[NOME COMPLETO]],Tb_EFETIVO[NOME COMPLETO],Tb_EFETIVO[SITUAÇÃO],"",0,1) -> ATIVO | E4: MOI | F4: 45922 | G4: =_xlfn.XLOOKUP(C4,Tb_FUNÇÕES[RESUMO - FUNÇÕES],Tb_FUNÇÕES[SALÁRIO BASE],"",0,1) -> 14000 | H4: =IF(tb_Custo[[#This Row],[TOMADOR]]="UTGC",tb_Custo[[#This Row],[SALÁRIO BASE]]*1.3,tb_Custo[[#This Row],[SALÁRIO BASE]]) -> 18200 | I4: 1100 | J4: 0 | K4: 246 | L4: 11.32 | M4: 5000 | N4: =tb_Custo[[#This Row],[SALÁRIO+PER]]*0.8 -> 14560 | O4: =SUM(tb_Custo[[#This Row],[SALÁRIO+PER]:[ENCARGOS TRABALHISTAS]]) -> 39117.32 | P4: =tb_Custo[[#This Row],[TOTAL INDIVIDUAL]]/$P$1 -> 177.806
A5: UTGC | B5: GEISON DE OLIVEIRA BEZERRA | C5: GERENTE DE CONTRATOS | D5: =_xlfn.XLOOKUP(tb_Custo[[#This Row],[NOME COMPLETO]],Tb_EFETIVO[NOME COMPLETO],Tb_EFETIVO[SITUAÇÃO],"",0,1) -> ATIVO | E5: MOI | F5: 45909 | G5: =_xlfn.XLOOKUP(C5,Tb_FUNÇÕES[RESUMO - FUNÇÕES],Tb_FUNÇÕES[SALÁRIO BASE],"",0,1) -> 12000 | H5: =IF(tb_Custo[[#This Row],[TOMADOR]]="UTGC",tb_Custo[[#This Row],[SALÁRIO BASE]]*1.3,tb_Custo[[#This Row],[SALÁRIO BASE]]) -> 15600 | I5: 1100 | J5: 0 | K5: 246 | L5: 11.32 | M5: 14800 | N5: =tb_Custo[[#This Row],[SALÁRIO+PER]]*0.8 -> 12480 | O5: =SUM(tb_Custo[[#This Row],[SALÁRIO+PER]:[ENCARGOS TRABALHISTAS]]) -> 44237.32 | P5: =tb_Custo[[#This Row],[TOTAL INDIVIDUAL]]/$P$1 -> 201.07873
A6: UTGC | B6: PABLO ALVES ZAMBI | C6: ENGENHEIRO PREPOSTO | D6: =_xlfn.XLOOKUP(tb_Custo[[#This Row],[NOME COMPLETO]],Tb_EFETIVO[NOME COMPLETO],Tb_EFETIVO[SITUAÇÃO],"",0,1) -> ATIVO | E6: MOI | F6: 45919 | G6: =_xlfn.XLOOKUP(C6,Tb_FUNÇÕES[RESUMO - FUNÇÕES],Tb_FUNÇÕES[SALÁRIO BASE],"",0,1) -> 12000 | H6: =IF(tb_Custo[[#This Row],[TOMADOR]]="UTGC",tb_Custo[[#This Row],[SALÁRIO BASE]]*1.3,tb_Custo[[#This Row],[SALÁRIO BASE]]) -> 15600 | I6: 1100 | J6: 0 | K6: 246 | L6: 11.32 | N6: =tb_Custo[[#This Row],[SALÁRIO+PER]]*0.8 -> 12480 | O6: =SUM(tb_Custo[[#This Row],[SALÁRIO+PER]:[ENCARGOS TRABALHISTAS]]) -> 29437.32 | P6: =tb_Custo[[#This Row],[TOTAL INDIVIDUAL]]/$P$1 -> 133.806
A7: UTGC | B7: WANDERSON LEAO DA SILVA | C7: COORDENADOR DE SMS | D7: =_xlfn.XLOOKUP(tb_Custo[[#This Row],[NOME COMPLETO]],Tb_EFETIVO[NOME COMPLETO],Tb_EFETIVO[SITUAÇÃO],"",0,1) -> ATIVO | E7: MOI | F7: 45931 | G7: =_xlfn.XLOOKUP(C7,Tb_FUNÇÕES[RESUMO - FUNÇÕES],Tb_FUNÇÕES[SALÁRIO BASE],"",0,1) -> 12000 | H7: =IF(tb_Custo[[#This Row],[TOMADOR]]="UTGC",tb_Custo[[#This Row],[SALÁRIO BASE]]*1.3,tb_Custo[[#This Row],[SALÁRIO BASE]]) -> 15600 | I7: 1100 | J7: 0 | K7: 492 | L7: 11.32 | N7: =tb_Custo[[#This Row],[SALÁRIO+PER]]*0.8 -> 12480 | O7: =SUM(tb_Custo[[#This Row],[SALÁRIO+PER]:[ENCARGOS TRABALHISTAS]]) -> 29683.32 | P7: =tb_Custo[[#This Row],[TOTAL INDIVIDUAL]]/$P$1 -> 134.92418
A8: EDIVIT | B8: PEDRO LUIZ LINS CARDOSO | C8: ENGENHEIRO DE PLANEJAMENTO | D8: =_xlfn.XLOOKUP(tb_Custo[[#This Row],[NOME COMPLETO]],Tb_EFETIVO[NOME COMPLETO],Tb_EFETIVO[SITUAÇÃO],"",0,1) -> ATIVO | E8: MOI | F8: 45917 | G8: =_xlfn.XLOOKUP(C8,Tb_FUNÇÕES[RESUMO - FUNÇÕES],Tb_FUNÇÕES[SALÁRIO BASE],"",0,1) -> 12000 | H8: =IF(tb_Custo[[#This Row],[TOMADOR]]="UTGC",tb_Custo[[#This Row],[SALÁRIO BASE]]*1.3,tb_Custo[[#This Row],[SALÁRIO BASE]]) -> 12000 | I8: 1254 | J8: 0 | K8: 246 | L8: 11.32 | M8: 3000 | N8: =tb_Custo[[#This Row],[SALÁRIO+PER]]*0.8 -> 9600 | O8: =SUM(tb_Custo[[#This Row],[SALÁRIO+PER]:[ENCARGOS TRABALHISTAS]]) -> 26111.32 | P8: =tb_Custo[[#This Row],[TOTAL INDIVIDUAL]]/$P$1 -> 118.68782
A9: EDIVIT | B9: RUBENS FREITAS ALBUQUERQUE | C9: ENGENHEIRO PREPOSTO | D9: =_xlfn.XLOOKUP(tb_Custo[[#This Row],[NOME COMPLETO]],Tb_EFETIVO[NOME COMPLETO],Tb_EFETIVO[SITUAÇÃO],"",0,1) -> ATIVO | E9: MOI | F9: 45917 | G9: =_xlfn.XLOOKUP(C9,Tb_FUNÇÕES[RESUMO - FUNÇÕES],Tb_FUNÇÕES[SALÁRIO BASE],"",0,1) -> 12000 | H9: =IF(tb_Custo[[#This Row],[TOMADOR]]="UTGC",tb_Custo[[#This Row],[SALÁRIO BASE]]*1.3,tb_Custo[[#This Row],[SALÁRIO BASE]]) -> 12000 | I9: 1254 | J9: 224.4 | K9: 246 | L9: 11.32 | N9: =tb_Custo[[#This Row],[SALÁRIO+PER]]*0.8 -> 9600 | O9: =SUM(tb_Custo[[#This Row],[SALÁRIO+PER]:[ENCARGOS TRABALHISTAS]]) -> 23335.72 | P9: =tb_Custo[[#This Row],[TOTAL INDIVIDUAL]]/$P$1 -> 106.07145
A10: UTGC | B10: MELVEN BILL DE SOUZA | C10: SUPERVISOR NIII | D10: =_xlfn.XLOOKUP(tb_Custo[[#This Row],[NOME COMPLETO]],Tb_EFETIVO[NOME COMPLETO],Tb_EFETIVO[SITUAÇÃO],"",0,1) -> ATIVO | E10: MOI | F10: 45943 | G10: =_xlfn.XLOOKUP(C10,Tb_FUNÇÕES[RESUMO - FUNÇÕES],Tb_FUNÇÕES[SALÁRIO BASE],"",0,1) -> 8500 | H10: =IF(tb_Custo[[#This Row],[TOMADOR]]="UTGC",tb_Custo[[#This Row],[SALÁRIO BASE]]*1.3,tb_Custo[[#This Row],[SALÁRIO BASE]]) -> 11050 | I10: 1100 | J10: 700 | K10: 246 | L10: 11.32 | N10: =tb_Custo[[#This Row],[SALÁRIO+PER]]*0.8 -> 8840 | O10: =SUM(tb_Custo[[#This Row],[SALÁRIO+PER]:[ENCARGOS TRABALHISTAS]]) -> 21947.32 | P10: =tb_Custo[[#This Row],[TOTAL INDIVIDUAL]]/$P$1 -> 99.760545
A11: UTGC | B11: YGOR GABRIEL DE SOUZA | C11: COORDENADOR ADMINISTRATIVO | D11: =_xlfn.XLOOKUP(tb_Custo[[#This Row],[NOME COMPLETO]],Tb_EFETIVO[NOME COMPLETO],Tb_EFETIVO[SITUAÇÃO],"",0,1) -> ATIVO | E11: MOI | F11: 45909 | G11: =_xlfn.XLOOKUP(C11,Tb_FUNÇÕES[RESUMO - FUNÇÕES],Tb_FUNÇÕES[SALÁRIO BASE],"",0,1) -> 8000 | H11: =IF(tb_Custo[[#This Row],[TOMADOR]]="UTGC",tb_Custo[[#This Row],[SALÁRIO BASE]]*1.3,tb_Custo[[#This Row],[SALÁRIO BASE]]) -> 10400 | I11: 1100 | J11: 0 | K11: 246 | L11: 11.32 | M11: 3000 | N11: =tb_Custo[[#This Row],[SALÁRIO+PER]]*0.8 -> 8320 | O11: =SUM(tb_Custo[[#This Row],[SALÁRIO+PER]:[ENCARGOS TRABALHISTAS]]) -> 23077.32 | P11: =tb_Custo[[#This Row],[TOTAL INDIVIDUAL]]/$P$1 -> 104.89691
A12: UTGC | B12: VALDELIO JOSE ALVES SILVA | C12: ENCARREGADO DE CALDERARIA | D12: =_xlfn.XLOOKUP(tb_Custo[[#This Row],[NOME COMPLETO]],Tb_EFETIVO[NOME COMPLETO],Tb_EFETIVO[SITUAÇÃO],"",0,1) -> ATIVO | E12: MOI | F12: 45919 | G12: =_xlfn.XLOOKUP(C12,Tb_FUNÇÕES[RESUMO - FUNÇÕES],Tb_FUNÇÕES[SALÁRIO BASE],"",0,1) -> 6525.36 | H12: =IF(tb_Custo[[#This Row],[TOMADOR]]="UTGC",tb_Custo[[#This Row],[SALÁRIO BASE]]*1.3,tb_Custo[[#This Row],[SALÁRIO BASE]]) -> 8482.968 | I12: 1100 | J12: 700 | K12: 984 | L12: 11.32 | N12: =tb_Custo[[#This Row],[SALÁRIO+PER]]*0.8 -> 6786.3744 | O12: =SUM(tb_Custo[[#This Row],[SALÁRIO+PER]:[ENCARGOS TRABALHISTAS]]) -> 18064.662 | P12: =tb_Custo[[#This Row],[TOTAL INDIVIDUAL]]/$P$1 -> 82.112102
A13: UTGC | B13: VALDEMIR MACHADO JARDIM | C13: ENCARREGADO CIVIL | D13: =_xlfn.XLOOKUP(tb_Custo[[#This Row],[NOME COMPLETO]],Tb_EFETIVO[NOME COMPLETO],Tb_EFETIVO[SITUAÇÃO],"",0,1) -> ATIVO | E13: MOI | F13: 45919 | G13: =_xlfn.XLOOKUP(C13,Tb_FUNÇÕES[RESUMO - FUNÇÕES],Tb_FUNÇÕES[SALÁRIO BASE],"",0,1) -> 6525.36 | H13: =IF(tb_Custo[[#This Row],[TOMADOR]]="UTGC",tb_Custo[[#This Row],[SALÁRIO BASE]]*1.3,tb_Custo[[#This Row],[SALÁRIO BASE]]) -> 8482.968 | I13: 1100 | J13: 700 | K13: 246 | L13: 11.32 | N13: =tb_Custo[[#This Row],[SALÁRIO+PER]]*0.8 -> 6786.3744 | O13: =SUM(tb_Custo[[#This Row],[SALÁRIO+PER]:[ENCARGOS TRABALHISTAS]]) -> 17326.662 | P13: =tb_Custo[[#This Row],[TOTAL INDIVIDUAL]]/$P$1 -> 78.757556
A14: EDIVIT | B14: ALEX GOMES DE OLIVEIRA | C14: ENCARREGADO DE CALDERARIA | D14: =_xlfn.XLOOKUP(tb_Custo[[#This Row],[NOME COMPLETO]],Tb_EFETIVO[NOME COMPLETO],Tb_EFETIVO[SITUAÇÃO],"",0,1) -> ATIVO | E14: MOI | F14: 46090 | G14: =_xlfn.XLOOKUP(C14,Tb_FUNÇÕES[RESUMO - FUNÇÕES],Tb_FUNÇÕES[SALÁRIO BASE],"",0,1) -> 6525.36 | H14: =IF(tb_Custo[[#This Row],[TOMADOR]]="UTGC",tb_Custo[[#This Row],[SALÁRIO BASE]]*1.3,tb_Custo[[#This Row],[SALÁRIO BASE]]) -> 6525.36 | I14: 0 | J14: 0 | K14: 0 | L14: 0 | N14: =tb_Custo[[#This Row],[SALÁRIO+PER]]*0.8 -> 5220.288 | O14: =SUM(tb_Custo[[#This Row],[SALÁRIO+PER]:[ENCARGOS TRABALHISTAS]]) -> 11745.648 | P14: =tb_Custo[[#This Row],[TOTAL INDIVIDUAL]]/$P$1 -> 53.389309
A15: EDIVIT | B15: DIRCEU CARAPINA | C15: ENCARREGADO DE CALDERARIA | D15: =_xlfn.XLOOKUP(tb_Custo[[#This Row],[NOME COMPLETO]],Tb_EFETIVO[NOME COMPLETO],Tb_EFETIVO[SITUAÇÃO],"",0,1) -> INATIVO | E15: MOI | F15: 45922 | G15: =_xlfn.XLOOKUP(C15,Tb_FUNÇÕES[RESUMO - FUNÇÕES],Tb_FUNÇÕES[SALÁRIO BASE],"",0,1) -> 6525.36 | H15: =IF(tb_Custo[[#This Row],[TOMADOR]]="UTGC",tb_Custo[[#This Row],[SALÁRIO BASE]]*1.3,tb_Custo[[#This Row],[SALÁRIO BASE]]) -> 6525.36 | I15: 1254 | J15: 0 | K15: 246 | L15: 11.32 | N15: =tb_Custo[[#This Row],[SALÁRIO+PER]]*0.8 -> 5220.288 | O15: =SUM(tb_Custo[[#This Row],[SALÁRIO+PER]:[ENCARGOS TRABALHISTAS]]) -> 13256.968 | P15: =tb_Custo[[#This Row],[TOTAL INDIVIDUAL]]/$P$1 -> 60.258945
A16: UTGC | B16: LEANDRO OTONI DA SILVA | C16: SOLDADOR | D16: =_xlfn.XLOOKUP(tb_Custo[[#This Row],[NOME COMPLETO]],Tb_EFETIVO[NOME COMPLETO],Tb_EFETIVO[SITUAÇÃO],"",0,1) -> ATIVO | E16: MOD | F16: 45967 | G16: =_xlfn.XLOOKUP(C16,Tb_FUNÇÕES[RESUMO - FUNÇÕES],Tb_FUNÇÕES[SALÁRIO BASE],"",0,1) -> 4975.62 | H16: =IF(tb_Custo[[#This Row],[TOMADOR]]="UTGC",tb_Custo[[#This Row],[SALÁRIO BASE]]*1.3,tb_Custo[[#This Row],[SALÁRIO BASE]]) -> 6468.306 | I16: 1100 | J16: 700 | K16: 246 | L16: 11.32 | N16: =tb_Custo[[#This Row],[SALÁRIO+PER]]*0.8 -> 5174.6448 | O16: =SUM(tb_Custo[[#This Row],[SALÁRIO+PER]:[ENCARGOS TRABALHISTAS]]) -> 13700.271 | P16: =tb_Custo[[#This Row],[TOTAL INDIVIDUAL]]/$P$1 -> 62.273958
A17: UTGC | B17: JONATHAN LOPES DOS SANTOS | C17: CALDEIREIRO ALPINISTA | D17: =_xlfn.XLOOKUP(tb_Custo[[#This Row],[NOME COMPLETO]],Tb_EFETIVO[NOME COMPLETO],Tb_EFETIVO[SITUAÇÃO],"",0,1) -> ATIVO | E17: MOD | F17: 45943 | G17: =_xlfn.XLOOKUP(C17,Tb_FUNÇÕES[RESUMO - FUNÇÕES],Tb_FUNÇÕES[SALÁRIO BASE],"",0,1) -> 4622.57 | H17: =IF(tb_Custo[[#This Row],[TOMADOR]]="UTGC",tb_Custo[[#This Row],[SALÁRIO BASE]]*1.3,tb_Custo[[#This Row],[SALÁRIO BASE]]) -> 6009.341 | I17: 1100 | J17: 700 | K17: 246 | L17: 11.32 | N17: =tb_Custo[[#This Row],[SALÁRIO+PER]]*0.8 -> 4807.4728 | O17: =SUM(tb_Custo[[#This Row],[SALÁRIO+PER]:[ENCARGOS TRABALHISTAS]]) -> 12874.134 | P17: =tb_Custo[[#This Row],[TOTAL INDIVIDUAL]]/$P$1 -> 58.51879
A18: UTGC | B18: MARCELO DOS SANTOS MATOS | C18: CALDEIREIRO ALPINISTA | D18: =_xlfn.XLOOKUP(tb_Custo[[#This Row],[NOME COMPLETO]],Tb_EFETIVO[NOME COMPLETO],Tb_EFETIVO[SITUAÇÃO],"",0,1) -> ATIVO | E18: MOD | F18: 45943 | G18: =_xlfn.XLOOKUP(C18,Tb_FUNÇÕES[RESUMO - FUNÇÕES],Tb_FUNÇÕES[SALÁRIO BASE],"",0,1) -> 4622.57 | H18: =IF(tb_Custo[[#This Row],[TOMADOR]]="UTGC",tb_Custo[[#This Row],[SALÁRIO BASE]]*1.3,tb_Custo[[#This Row],[SALÁRIO BASE]]) -> 6009.341 | I18: 1100 | J18: 700 | K18: 738 | L18: 11.32 | N18: =tb_Custo[[#This Row],[SALÁRIO+PER]]*0.8 -> 4807.4728 | O18: =SUM(tb_Custo[[#This Row],[SALÁRIO+PER]:[ENCARGOS TRABALHISTAS]]) -> 13366.134 | P18: =tb_Custo[[#This Row],[TOTAL INDIVIDUAL]]/$P$1 -> 60.755154
A19: UTGC | B19: PABLO CORREIA COSME | C19: CALDEIREIRO ALPINISTA | D19: =_xlfn.XLOOKUP(tb_Custo[[#This Row],[NOME COMPLETO]],Tb_EFETIVO[NOME COMPLETO],Tb_EFETIVO[SITUAÇÃO],"",0,1) -> ATIVO | E19: MOD | F19: 45992 | G19: =_xlfn.XLOOKUP(C19,Tb_FUNÇÕES[RESUMO - FUNÇÕES],Tb_FUNÇÕES[SALÁRIO BASE],"",0,1) -> 4622.57 | H19: =IF(tb_Custo[[#This Row],[TOMADOR]]="UTGC",tb_Custo[[#This Row],[SALÁRIO BASE]]*1.3,tb_Custo[[#This Row],[SALÁRIO BASE]]) -> 6009.341 | I19: 1100 | J19: 700 | K19: 246 | L19: 11.32 | N19: =tb_Custo[[#This Row],[SALÁRIO+PER]]*0.8 -> 4807.4728 | O19: =SUM(tb_Custo[[#This Row],[SALÁRIO+PER]:[ENCARGOS TRABALHISTAS]]) -> 12874.134 | P19: =tb_Custo[[#This Row],[TOTAL INDIVIDUAL]]/$P$1 -> 58.51879
A20: UTGC | B20: WENDELL DOS SANTOS CARLOS | C20: CALDEIREIRO ALPINISTA | D20: =_xlfn.XLOOKUP(tb_Custo[[#This Row],[NOME COMPLETO]],Tb_EFETIVO[NOME COMPLETO],Tb_EFETIVO[SITUAÇÃO],"",0,1) -> ATIVO | E20: MOD | F20: 45943 | G20: =_xlfn.XLOOKUP(C20,Tb_FUNÇÕES[RESUMO - FUNÇÕES],Tb_FUNÇÕES[SALÁRIO BASE],"",0,1) -> 4622.57 | H20: =IF(tb_Custo[[#This Row],[TOMADOR]]="UTGC",tb_Custo[[#This Row],[SALÁRIO BASE]]*1.3,tb_Custo[[#This Row],[SALÁRIO BASE]]) -> 6009.341 | I20: 1063.34 | J20: 700 | K20: 492 | L20: 11.32 | N20: =tb_Custo[[#This Row],[SALÁRIO+PER]]*0.8 -> 4807.4728 | O20: =SUM(tb_Custo[[#This Row],[SALÁRIO+PER]:[ENCARGOS TRABALHISTAS]]) -> 13083.474 | P20: =tb_Custo[[#This Row],[TOTAL INDIVIDUAL]]/$P$1 -> 59.470335
A21: UTGC | B21: MARCOS VINICIUS SANTOS DE SOUZA MATOS | C21: TECNICO SEGURANÇA DO TRABALHO | D21: =_xlfn.XLOOKUP(tb_Custo[[#This Row],[NOME COMPLETO]],Tb_EFETIVO[NOME COMPLETO],Tb_EFETIVO[SITUAÇÃO],"",0,1) -> ATIVO | E21: MOI | F21: 46083 | G21: =_xlfn.XLOOKUP(C21,Tb_FUNÇÕES[RESUMO - FUNÇÕES],Tb_FUNÇÕES[SALÁRIO BASE],"",0,1) -> 4425.3 | H21: =IF(tb_Custo[[#This Row],[TOMADOR]]="UTGC",tb_Custo[[#This Row],[SALÁRIO BASE]]*1.3,tb_Custo[[#This Row],[SALÁRIO BASE]]) -> 5752.89 | I21: 0 | J21: 0 | K21: 0 | L21: 0 | N21: =tb_Custo[[#This Row],[SALÁRIO+PER]]*0.8 -> 4602.312 | O21: =SUM(tb_Custo[[#This Row],[SALÁRIO+PER]:[ENCARGOS TRABALHISTAS]]) -> 10355.202 | P21: =tb_Custo[[#This Row],[TOTAL INDIVIDUAL]]/$P$1 -> 47.0691
A22: UTGC | B22: RAFAEL DOS SANTOS ARAUJO | C22: TECNICO DE PLANEJAMENTO | D22: =_xlfn.XLOOKUP(tb_Custo[[#This Row],[NOME COMPLETO]],Tb_EFETIVO[NOME COMPLETO],Tb_EFETIVO[SITUAÇÃO],"",0,1) -> ATIVO | E22: MOI | F22: 45917 | G22: =_xlfn.XLOOKUP(C22,Tb_FUNÇÕES[RESUMO - FUNÇÕES],Tb_FUNÇÕES[SALÁRIO BASE],"",0,1) -> 4425.3 | H22: =IF(tb_Custo[[#This Row],[TOMADOR]]="UTGC",tb_Custo[[#This Row],[SALÁRIO BASE]]*1.3,tb_Custo[[#This Row],[SALÁRIO BASE]]) -> 5752.89 | I22: 1100 | J22: 700 | K22: 738 | L22: 11.32 | N22: =tb_Custo[[#This Row],[SALÁRIO+PER]]*0.8 -> 4602.312 | O22: =SUM(tb_Custo[[#This Row],[SALÁRIO+PER]:[ENCARGOS TRABALHISTAS]]) -> 12904.522 | P22: =tb_Custo[[#This Row],[TOTAL INDIVIDUAL]]/$P$1 -> 58.656918
A23: UTGC | B23: RAFAEL RIBEIRO DE CASTRO | C23: TECNICO SEGURANÇA DO TRABALHO | D23: =_xlfn.XLOOKUP(tb_Custo[[#This Row],[NOME COMPLETO]],Tb_EFETIVO[NOME COMPLETO],Tb_EFETIVO[SITUAÇÃO],"",0,1) -> ATIVO | E23: MOI | F23: 45917 | G23: =_xlfn.XLOOKUP(C23,Tb_FUNÇÕES[RESUMO - FUNÇÕES],Tb_FUNÇÕES[SALÁRIO BASE],"",0,1) -> 4425.3 | H23: =IF(tb_Custo[[#This Row],[TOMADOR]]="UTGC",tb_Custo[[#This Row],[SALÁRIO BASE]]*1.3,tb_Custo[[#This Row],[SALÁRIO BASE]]) -> 5752.89 | I23: 1100 | J23: 700 | K23: 738 | L23: 11.32 | N23: =tb_Custo[[#This Row],[SALÁRIO+PER]]*0.8 -> 4602.312 | O23: =SUM(tb_Custo[[#This Row],[SALÁRIO+PER]:[ENCARGOS TRABALHISTAS]]) -> 12904.522 | P23: =tb_Custo[[#This Row],[TOTAL INDIVIDUAL]]/$P$1 -> 58.656918
... A84: EDIVIT | B84: THIAGO FERREIRA DA COSTA | C84: AJUDANTE DE OBRAS | D84: =_xlfn.XLOOKUP(tb_Custo[[#This Row],[NOME COMPLETO]],Tb_EFETIVO[NOME COMPLETO],Tb_EFETIVO[SITUAÇÃO],"",0,1) -> ATIVO | E84: MOD | F84: 45938 | G84: =_xlfn.XLOOKUP(C84,Tb_FUNÇÕES[RESUMO - FUNÇÕES],Tb_FUNÇÕES[SALÁRIO BASE],"",0,1) -> 1726.63 | H84: =IF(tb_Custo[[#This Row],[TOMADOR]]="UTGC",tb_Custo[[#This Row],[SALÁRIO BASE]]*1.3,tb_Custo[[#This Row],[SALÁRIO BASE]]) -> 1726.63 | I84: 1254 | J84: 224.4 | K84: 246 | L84: 11.32 | N84: =tb_Custo[[#This Row],[SALÁRIO+PER]]*0.8 -> 1381.304 | O84: =SUM(tb_Custo[[#This Row],[SALÁRIO+PER]:[ENCARGOS TRABALHISTAS]]) -> 4843.654 | P84: =tb_Custo[[#This Row],[TOTAL INDIVIDUAL]]/$P$1 -> 22.016609

Sheet SUBCONTRATADOS
A1: TOMADOR | B1: SINDICATO | C1: NOME COMPLETO | D1: FUNÇÃO | E1: SALÁRIO BASE | F1: SALÁRIO+PER | G1: ID COLAB | H1: TIPO | I1: ADMISSÃO | J1: NASCIMENTO | K1: CPF | L1: DEMISSÃO
A3: TOMADOR | B3: SINDICATO | C3: NOME COMPLETO | D3: FUNÇÃO | E3: SALARIO BASE | F3: ID FUNCIONÁRIO | G3: EMPRESA | H3: ADMISSÃO | I3: NASCIMENTO | J3: CPF | K3: DEMISSÃO | L3: SITUAÇÃO
A4: EDIVIT | C4: ISRAEL DOS SANTOS | D4: MECANICO MONTADOR | E4: 1 | G4: TORRES DO BRASIL | H4: 44279 | J4: 16856185880 | L4: ATIVO
A5: EDIVIT | C5: LUIZ CARLOS LOPES | D5: MECANICO MONTADOR | E5: 1 | G5: TORRES DO BRASIL | H5: 44279 | J5: 66748992915 | L5: ATIVO
A6: EDIVIT | C6: MARCIO AUGUSTO RAMOS GALDINO | D6: MECANICO MONTADOR | E6: 1 | G6: TORRES DO BRASIL | H6: 44279 | J6: 42402176873 | L6: ATIVO
A7: UTGC | C7: FELIPE DE QUEIROZ SILVA | D7: OPERADOR MUCK | E7: 1 | F7: 72753637 | G7: AQUARIUS | H7: 45524 | I7: 33298 | J7: 13929352702 | L7: ATIVO
A8: UTGC | C8: JONAS GOMES DOS SANTOS | D8: RIGGER | E8: 1 | F8: 47247651 | G8: AQUARIUS | H8: 45736 | I8: 31094 | J8: 10185591752 | L8: ATIVO
A9: UTGC | C9: ANDERSON ALLAN DE CARVALHO ARAUJO | D9: OPERADOR MUCK | E9: 1 | F9: 72910438 | G9: AQUARIUS | H9: 45982 | I9: 30247 | J9: 11036849732 | L9: ATIVO
A10: UTGC | C10: WAGNER NOGUEIRA DIVINO | D10: OPERADOR DE GUINDASTE | E10: 1 | F10: 71092138 | G10: AQUARIUS | H10: 44226 | I10: 29900 | J10: 09118973728 | L10: ATIVO
A11: UTGC | C11: GABRIEL SILVA DE ALMEIDA | D11: RIGGER | E11: 1 | F11: 72103801 | G11: AQUARIUS | H11: 45964 | I11: 37040 | J11: 17040087782 | L11: ATIVO
A12: UTGC | C12: AELTON SOUZA BENTO | D12: LIDER DE ANDAIME | E12: 1 | F12: 43194397 | G12: ENGEVAL | H12: 44827 | J12: 01787021530 | L12: ATIVO
A13: UTGC | C13: EWERTON FLORO DOS SANTOS | D13: AJUDANTE DE MONTAGEM | E13: 1 | F13: 72623394 | G13: ENGEVAL | H13: 45777 | J13: 14772241736 | L13: ATIVO
A14: UTGC | C14: JACKSON VIDEO GOMES | D14: MONTADOR DE ANDAIMES | E14: 1 | F14: 72454662 | G14: ENGEVAL | H14: 45609 | J14: 11308157738 | L14: ATIVO
A15: UTGC | C15: JOSE ALBERTO BARBOSA CASTRO | D15: MONTADOR DE ANDAIMES | E15: 1 | F15: 72900064 | G15: ENGEVAL | H15: 45993 | J15: 67045359268 | L15: ATIVO
A16: UTGC | C16: LEANDRO CESAR GUIMARES | D16: MONTADOR DE ANDAIMES | E16: 1 | F16: 47488679 | G16: ENGEVAL | H16: 45993 | J16: 1255901560 | L16: ATIVO
A17: UTGC | C17: ROMARIO OLIVEIRA ALVES | D17: ENCARREGADO DE ANDAIMES | E17: 1 | F17: 49923733 | G17: ENGEVAL | H17: 44827 | J17: 14420294710 | L17: ATIVO
A18: UTGC | C18: UANDERSON RAMOS SILVA | D18: MONTADOR DE ANDAIMES | E18: 1 | F18: 49017693 | G18: ENGEVAL | H18: 45777 | J18: 12766190732 | L18: ATIVO
A19: UTGC | C19: FELIPE SANTOS DA VITORIA | D19: MONTADOR DE ANDAIMES | E19: 1 | F19: 72106575 | G19: ENGEVAL | H19: 46034 | J19: 18327560760 | L19: ATIVO
A20: UTGC | C20: FERNANDO SILVA ROCHA | D20: AJUDANTE DE MONTAGEM | E20: 1 | F20: 72947677 | G20: ENGEVAL | H20: 46034 | J20: 15505709788 | L20: ATIVO
A21: UTGC | C21: VINICIUS COUTINHO PEREIRA MATOS | D21: MONTADOR DE ANDAIMES | E21: 1 | F21: 72077354 | G21: ENGEVAL | H21: 46034 | J21: 14372009747 | L21: ATIVO
A22: UTGC | C22: ALEX MARRONE FARIAS FERREIRA | D22: MONTADOR DE ANDAIMES | E22: 1 | F22: 72980987 | G22: ENGEVAL | H22: 46071 | J22: 07593389570 | L22: ATIVO
A23: UTGC | C23: ELISSON GUSMÃO DOS SANTOS | D23: MONTADOR DE ANDAIMES | E23: 1 | F23: 71742060 | G23: ENGEVAL | H23: 46071 | J23: 86690009548 | L23: ATIVO
A24: UTGC | C24: LEONARDO DA SILVA SANTOS | D24: MONTADOR DE ANDAIMES | E24: 1 | F24: 72981185 | G24: ENGEVAL | H24: 46071 | J24: 86047687504 | L24: ATIVO
A25: UTGC | C25: MARCONDES DE JESUS MEIRA | D25: MONTADOR DE ANDAIMES | E25: 1 | F25: 72975990 | G25: ENGEVAL | H25: 46071 | J25: 04588972561 | L25: ATIVO
A26: UTGC | C26: WASHINGTON BORGES DA CRUZ | D26: ENCARREGADO DE ANDAIMES | E26: 1 | F26: 45030269 | G26: ENGEVAL | H26: 46071 | J26: 03433937516 | L26: ATIVO
B35: =UPPER(B27)

Sheet E-MAIL'S
B1: =EFETIVO!N1 -> ATUALIZAÇÃO: 09/03/2026 | C1: CONTROLE DE ATIVOS E INATIVOS: ES|MG
B2: TOTAL:
B3: =SUBTOTAL(3,Tb_EMAILGESTAO[NOME]) -> 20
A4: SETOR | B4: TOMADOR | C4: NOME | D4: FUNÇÃO | E4: EMAIL
A5: SMS | B5: EDIVIT | C5: MARCOS ARAUJO RIBEIRO | D5: TECNICO SEGURANÇA DO TRABALHO | E5: marcos.ribeiro@apjpetro.com.br
A6: SMS | B6: EDIVIT | C6: BRAYON LOPES DA SILVA | D6: TECNICO SEGURANÇA DO TRABALHO | E6: brayon.silva@apjpetro.com.br
A7: ADMINISTRAÇÃO | B7: EDIVIT | C7: EDCASSIA RIBEIRO GOMES DUTRA | D7: ASSISTENTE ADMINISTRATIVA | E7: edcassia.dutra@apjpetro.com.br
A8: PLANEJAMENTO | B8: UTGC | C8: ELISEU GOMES | D8: TECNICO DE PLANEJAMENTO | E8: eliseu.gomes@apjpetro.com.br
A9: GERÊNCIA | B9: UTGC | C9: GEISON DE OLIVEIRA BEZERRA | D9: GERENTE DE CONTRATO | E9: geison.bezerra@apjpetro.com.br
A10: ADMINISTRAÇÃO | B10: UTGC | C10: IARA MARIA TEIXEIRA | D10: ASSISTENTE ADMINISTRATIVA | E10: iara.teixeira@apjpetro.com.br
A11: PLANEJAMENTO | B11: UTGC | C11: KERGINALDO VICTOR DA SILVA FILHO | D11: ENGENHEIRO DE PLANEJAMENTO | E11: kerginaldo.victor@apjpetro.com.br
A12: ADMINISTRAÇÃO | B12: UTGC | C12: PABLO ALVES ZAMBI | D12: COORDENADOR OPERACIONAL | E12: pablo.alves@apjpetro.com.br
A13: PLANEJAMENTO | B13: EDIVIT | C13: PEDRO LUIZ LINS CARDOSO | D13: ENGENHEIRO DE PLANEJAMENTO | E13: pedro.luiz@apjpetro.com.br
A14: PLANEJAMENTO | B14: UTGC | C14: RAFAEL DOS SANTOS ARAUJO | D14: TECNICO DE PLANEJAMENTO | E14: rafael.santos@apjpetro.com.br
A15: SMS | B15: UTGC | C15: RAFAEL RIBEIRO DE CASTRO | D15: TECNICO SEGURANÇA DO TRABALHO | E15: rafael.castro@apjpetro.com.br
... A24: ALMOXARIFADO | B24: UTGC | C24: VALDINEY GOMES MARIA DOS SANTOS | D24: ALMOXARIFE DE OBRAS | E24: valdiney.santos@apjpetro.com.br

Sheet ACORDO SINDICATO
E4: COLABORADOR NOME | F4: ACEITO (ASSINATURA) | G4: NÃO ACEITO (ASSINATURA)
E5: AGUINALDO KRULL CUSTÓDIO
E6: ALISON PEREIRA BARBOSA
E7: ANGELO GABRIEL DE ALMEIDA SILVA
E8: ANTONIO DOMINGOS DOS SANTOS JUNIOR
E9: CARLOS DA CONCEIÇÃO DE SOUZA
E10: DEYVID ALAN OLIVEIRA MUNIZ
E11: DIEKSON VALERIANO DOS REIS
E12: DONIZETE DA CONCEIÇÃO SILVA
E13: DOUGLIAN MORAES TIMBUIBA
E14: EDNALDO SANTOS FLORES
E15: EDUARDO INACIA COSTA
E16: ELIVALDO DE OLIVEIRA
... E67: YGOR GABRIEL DE SOUZA

Sheet AUX
A1: RESUMO - FUNÇÕES | B1: SALÁRIO BASE | D1: DIA | E1: FERIADO UTGC | G1: DIA | H1: FERIADO EDIVIT | J1: TOMADOR | K1: MOD | L1: MOI | M1: SUB | N1: TOTAL
A2: AJUDANTE DE CALDEIRARIA | B2: 1726.63 | D2: 45658 | E2: Ano Novo | G2: 45658 | H2: Ano Novo | J2: EDIVIT | K2: =COUNTIFS(Tb_EFETIVO[TOMADOR],AUX!J2,Tb_EFETIVO[SITUAÇÃO],"ATIVO",Tb_EFETIVO[TIPO],AUX!K1) -> 9 | L2: =COUNTIFS(Tb_EFETIVO[TOMADOR],AUX!J2,Tb_EFETIVO[SITUAÇÃO],"ATIVO",Tb_EFETIVO[TIPO],AUX!L1) -> 9 | M2: =COUNTIFS(tb_SUB[TOMADOR],AUX!J2,tb_SUB[DEMISSÃO],"ATIVO") -> 0 | N2: =SUM(K2:M2) -> 18
A3: AJUDANTE DE CIVIL | B3: 1726.63 | D3: 45719 | E3: Carnaval | G3: 45719 | H3: Carnaval | J3: UTGC | K3: =COUNTIFS(Tb_EFETIVO[TOMADOR],AUX!J3,Tb_EFETIVO[SITUAÇÃO],"ATIVO",Tb_EFETIVO[TIPO],AUX!K1) -> 46 | L3: =COUNTIFS(Tb_EFETIVO[TOMADOR],AUX!J3,Tb_EFETIVO[SITUAÇÃO],"ATIVO",Tb_EFETIVO[TIPO],AUX!L1) -> 16 | M3: =COUNTIFS(tb_SUB[TOMADOR],AUX!J3,tb_SUB[DEMISSÃO],"ATIVO") -> 0 | N3: =SUM(K3:M3) -> 62
A4: AJUDANTE DE OBRAS | B4: 1726.63 | D4: 45720 | E4: Carnaval | G4: 45720 | H4: Carnaval | N4: =SUM(N2:N3) -> 80
A5: AJUDANTE DE PINTURA | B5: 1726.63 | D5: 45721 | E5: Cinzas | G5: 45721 | H5: Cinzas | J5: DIAS ÚTEIS TRABALHO
A6: ALMOXARIFE DE OBRAS | B6: 3000 | D6: 45765 | E6: Sexta-Feira Santa | G6: 45765 | H6: Sexta-Feira Santa | J6: MÊS | K6: UTGC | L6: EDIVIT
A7: ASSISTENTE ADMINISTRATIVO | B7: 3800 | D7: 45768 | E7: Dia de Tiradentes | G7: 45768 | H7: Dia de Tiradentes | J7: FEVEREIRO/26 | K7: =NETWORKDAYS(DATE(2026,2,1),DATE(2026,2,28),Tb_feriadoUTGC[DIA]) -> 17 | L7: =NETWORKDAYS(DATE(2026,2,1),DATE(2026,2,28),Tb_feriadoEDIVIT[DIA]) -> 17
A8: CALDEIREIRO | B8: 4402.45 | D8: 45775 | E8: Nossa Senhora da Penha | G8: 45775 | H8: Nossa Senhora da Penha
A9: CALDEIREIRO ALPINISTA | B9: 4622.57 | D9: 45778 | E9: Dia do Trabalho | G9: 45778 | H9: Dia do Trabalho
A10: COMPRADOR | B10: 4425.3 | D10: 45827 | E10: Corpus Christi | G10: 45827 | H10: Corpus Christi
A11: COORDENADOR ADMINISTRATIVO | B11: 8000 | D11: 45891 | E11: Dia dos Linhares | G11: 45907 | H11: Independência do Brasil
A12: COORDENADOR DE PLANEJAMENTO | B12: 14000 | D12: 45907 | E12: Independência do Brasil | G12: 45908 | H12: Nossa Senhora da Vitória
A13: COORDENADOR DE SMS | B13: 12000 | D13: 45936 | E13: Nossa Senhora Aparecida | G13: 45936 | H13: Dia da Construção Civil
A14: ELETRICISTA | B14: 3328.48 | D14: 45942 | E14: Nossa Senhora Aparecida | G14: 45942 | H14: Nossa Senhora Aparecida
A15: ENCARREGADO CIVIL | B15: 6525.36 | D15: 45963 | E15: Dia de Finados | G15: 45963 | H15: Dia de Finados
A16: ENCARREGADO DE ANDAIMES | B16: 6525.36 | D16: 45976 | E16: Proclamação da República | G16: 45976 | H16: Proclamação da República
A17: ENCARREGADO DE CALDERARIA | B17: 6525.36 | D17: 45981 | E17: Consciência Negra | G17: 45981 | H17: Consciência Negra
A18: ENGENHEIRO DE PLANEJAMENTO | B18: 12000 | D18: 45999 | E18: Dia de Nossa Senhora da Conceição | G18: 46016 | H18: Natal
A19: ENGENHEIRO ORÇAMENTISTA | B19: 14000 | D19: 46016 | E19: Natal | G19: 46023 | H19: Ano Novo
... A34: TECNICO SEGURANÇA DO TRABALHO | B34: 4425.3 | D34: 46346 | E34: Consciência Negra | G34: 46381 | H34: Natal
D35: 46364 | E35: Dia de Nossa Senhora da Conceição
D36: 46381 | E36: Natal

Sheet ACORDO UTGC
B2: NOME COLABORADOR | C2: ACEITO (ASSINATURA) | D2: NÃO ACEITO (ASSINATURA)
B3: AGUINALDO KRULL CUSTÓDIO
B4: ALISON PEREIRA BARBOSA
B5: ANTONIO DOMINGOS DOS SANTOS JUNIOR
B6: CARLOS DA CONCEIÇÃO DE SOUZA
B7: DANIEL DA CONCEIÇÃO FLORO JUNIOR
B8: DEYVID ALAN OLIVEIRA MUNIZ
B9: DIEKSON VALERIANO DOS REIS
B10: DONIZETE DA CONCEIÇÃO SILVA
B11: EDINALDO SILVA DOS ANJOS JUNIOR
B12: EDUARDO ANDRADE CECILIO
B13: ELIVALDO DE OLIVEIRA
B14: ENEAS SANTANA DA SILVA
... B60: YGOR GABRIEL DE SOUZA

Sheet ACORDO EDIVIT
B2: COLABORADOR NOME | C2: ACEITO (ASSINATURA) | D2: NÃO ACEITO (ASSINATURA)
B3: ADENILDO LARANJEIRA DOS SANTOS
B4: AIRYS DAVIDSON PEREIRA DOS SANTOS
B5: ALBERTO COSTA DE JESUS
B6: BRAYON LOPES DA SILVA
B7: DANIEL NUNES MOTA
B8: DIRCEU CARAPINA
B9: EDCASSIA RIBEIRO GOMES DUTRA
B10: ELISEU GOMES
B11: FELIPE KAYAN FAUSTINO FERREIRA
B12: FELIPE SOARES CAMPOS
B13: GUSTAVO FRANCO DE SANTANA
B14: JALDES BARBOSA ANDRADE
... B23: THIAGO FERREIRA DA COSTA
